Workbook

Sheet DOMINGO
C1: ENFOQUE DIARIO! - Nuestra meta | H1: Semana: | I1: 30 | J1: Día: | K1: 46239 | L1: Tienda: | M1: VALLEJO | P1: LAS CELDAS EN COLOR VERDE SE LLENAN AUTOMÁTICAMENTE
A2: ¿QÚE ESPERAMOS LOGRAR HOY?
B4: META DEL DÍA | E4: CONVERSIÓN (NO NEGOCIABLE) | H4: OTROS NO NEGOCIABLES | J4: UNIDADES | L4: META DE PRODUCTIVIDAD | P4: CAPTURA LOS VALORES DEL DÍA COMP
B5: META DIARIA | C5: 4758 | E5: TRÁFICO ESPERADO | F5: 8 | H5: WEARABLES | I5: 0.15 | J5: =IF(C7/8100<1,1,C7/8100) -> 1 | L5: VENTA NETA (NS) | M5: =C5/D25 -> 475.8
B6: ANÁLOGOS | C6: =C5*0.85 -> 4044.3 | E6: META DE CONVERSIÓN (LY+1P.P) | F6: 0.13 | H6: KIDS | I6: 0.05 | J6: =IF(+C8*I6<1,1,C8*I6) -> 1 | L6: UNIDADES | M6: =C8/D25 -> 0.10305393 | P6: ATV
B7: WEARABLES | C7: =+C5*0.15 -> 713.7 | E7: META TRANSACCIONES | F7: =+F5*F6 -> 1.04 | H7: CAREKITS | I7: 0.3 | J7: =IF(C8*I7<1,1,C8*I7) -> 1 | P7: 7500
B8: TOTAL DE UNIDADES | C8: =+C5/P9 -> 1.0305393 | E8: META IDEAL (NS)* | F8: =+C5*1.1 -> 5233.8 | I8: *Si las unidades dan como resultado menor a cero, el objetivo será mínimo una unidad. | L8: COMP LY | P8: AUR
E9: *Si tienes adeudo en la semana puedes ajustar la meta ideal | L9: VENTA NETA LY (NS) | M9: 4758 | P9: 4617
P10: CAPTURA LOS VALORES ACUMULADOS DEL MES (MTD)
C11: APERTURA-1pm | D11: 1pm - 3pm | E11: 3pm-5pm | F11: 5pm-7pm | G11: 7pm-CIERRE | H11: TOTAL
B12: TRÁFICO POR HORA | C12: 4 | D12: 2 | E12: 2 | F12: 0 | G12: 0 | H12: =SUM(C12:G12) -> 8 | P12: ATV
B13: PESO DEL TRÁFICO (%) | C13: =+C12/$H$12 -> 0.5 | D13: =+D12/$H$12 -> 0.25 | E13: =+E12/$H$12 -> 0.25 | F13: =+F12/$H$12 -> 0 | G13: =+G12/$H$12 -> 0 | P13: 6578
B14: META (NS) X HORA | C14: =+C13*$C$5 -> 2379 | D14: =+D13*$C$5 -> 1189.5 | E14: =+E13*$C$5 -> 1189.5 | F14: =+F13*$C$5 -> 0 | G14: =+G13*$C$5 -> 0 | H14: =+SUM(C14:G14) -> 4758 | P14: AUR
P15: 4312
B16: COLABORADORES | D16: HORAS PROGRAMADAS | E16: META DE VENTA | F16: ANALOGOS POR VENDER | G16: WEARABLES POR VENDER | H16: KIDS POR VENDER | I16: CK POR VENDER | L16: Además de cumplir con la meta diaria de la tienda para los No Negociables, cada colaborador debe procurar vender durante su turno al menos: 1 armazón Kids 1 CareKit
B17: VIVIANA | D17: 10 | E17: =($C$5/$D$25)*D17 -> 4758 | F17: =IF((($C$8-$J$5)/$D$25)*D17<1,1,((($C$8-$J$5)/$D$25)*D17)) -> 1 | H17: =IF(D17>0,MAX(($J$6/$D$25)*D17,1),0) -> 1 | I17: =IF(D17>0,MAX(($J$7/$D$25)*D17,1),0) -> 1
E18: =($C$5/$D$25)*D18 -> 0 | F18: =IF((($C$8-$J$5)/$D$25)*D18<1,1,((($C$8-$J$5)/$D$25)*D18)) -> 1 | H18: =IF(D18>0,MAX(($J$6/$D$25)*D18,1),0) -> 0 | I18: =IF(D18>0,MAX(($J$7/$D$25)*D18,1),0) -> 0
E19: =($C$5/$D$25)*D19 -> 0 | F19: =IF((($C$8-$J$5)/$D$25)*D19<1,1,((($C$8-$J$5)/$D$25)*D19)) -> 1 | H19: =IF(D19>0,MAX(($J$6/$D$25)*D19,1),0) -> 0 | I19: =IF(D19>0,MAX(($J$7/$D$25)*D19,1),0) -> 0
E20: =($C$5/$D$25)*D20 -> 0 | F20: =IF((($C$8-$J$5)/$D$25)*D20<1,1,((($C$8-$J$5)/$D$25)*D20)) -> 1 | H20: =IF(D20>0,MAX(($J$6/$D$25)*D20,1),0) -> 0 | I20: =IF(D20>0,MAX(($J$7/$D$25)*D20,1),0) -> 0
E21: =($C$5/$D$25)*D21 -> 0 | F21: =IF((($C$8-$J$5)/$D$25)*D21<1,1,((($C$8-$J$5)/$D$25)*D21)) -> 1 | H21: =IF(D21>0,MAX(($J$6/$D$25)*D21,1),0) -> 0 | I21: =IF(D21>0,MAX(($J$7/$D$25)*D21,1),0) -> 0
E22: =($C$5/$D$25)*D22 -> 0 | F22: =IF((($C$8-$J$5)/$D$25)*D22<1,1,((($C$8-$J$5)/$D$25)*D22)) -> 1 | H22: =IF(D22>0,MAX(($J$6/$D$25)*D22,1),0) -> 0 | I22: =IF(D22>0,MAX(($J$7/$D$25)*D22,1),0) -> 0
E23: =($C$5/$D$25)*D23 -> 0 | F23: =IF((($C$8-$J$5)/$D$25)*D23<1,1,((($C$8-$J$5)/$D$25)*D23)) -> 1 | H23: =IF(D23>0,MAX(($J$6/$D$25)*D23,1),0) -> 0 | I23: =IF(D23>0,MAX(($J$7/$D$25)*D23,1),0) -> 0
E24: =($C$5/$D$25)*D24 -> 0 | F24: =IF((($C$8-$J$5)/$D$25)*D24<1,1,((($C$8-$J$5)/$D$25)*D24)) -> 1 | H24: =IF(D24>0,MAX(($J$6/$D$25)*D24,1),0) -> 0 | I24: =IF(D24>0,MAX(($J$7/$D$25)*D24,1),0) -> 0
B25: TOTAL | C25: TOTAL | D25: =+SUM(D17:D24) -> 10 | E25: =SUM(E17:E24) -> 4758 | F25: =SUM(F17:F24) -> 8 | G25: =SUM(G17:G24) -> 0 | H25: =+J6 -> 1 | I25: =+J7 -> 1
A27: ¿CÓMO VAMOS?
D29: META | E29: VENTA NETA | F29: META UNIDADES | G29: VENTA UNIDADES | H29: CONVERSION (%) | I29: CRECIMIENTO CONVERSION (%) | J29: WEARABLES % | K29: KIDS% | L29: CAREKITS% | M29: SLP | O29: ONESIGHT
B30: TOTAL DEL DÍA | C30: TOTAL | D30: =+C5 -> 4758 | E30: 25600 | F30: =+C8 -> 1.0305393 | G30: 5 | H30: =G41/E41 -> 0.23076923 | I30: =H30-F6 -> 0.10076923 | J30: 0.316 | K30: 0.111 | L30: =P41/G30 -> 0.2
B32: COLABORADOR | D32: HORAS PROGRAMADAS | E32: INTERACCIONES DURANTE EL DÍA | G32: CLIENTES CONVERTIDOS DURANTE EL DÍA | I32: CONVERSION AL CIERRE | J32: VENTA NETA AL CIERRE | K32: UNIDADES ANALOGAS AL CIERRE | L32: DEMOSTRACIONES WEARABLES AL CIERRE | M32: UNIDADES WEARABLES AL CIERRE | N32: CONVERSION WEREABLE | O32: KIDS AL CIERRE | P32: CAREKITS AL CIERRE | Q32: SLP EOD
B33: =B17 -> VIVIANA | D33: =D17 -> 10 | E33: 6 | G33: 1 | I33: =IFERROR(G33/E33,"0") -> 0.16666667 | J33: 13456 | K33: 2 | L33: 3 | M33: 1 | N33: =IFERROR(M33/L33,"0") -> 0.33333333 | O33: 1 | P33: 1
B34: =B18 -> 0 | D34: =D18 -> 0 | E34: 4 | G34: 1 | I34: =IFERROR(G34/E34,"0") -> 0.25 | J34: 9344 | K34: 1 | L34: 1 | M34: 0 | N34: =IFERROR(M34/L34,"0") -> 0 | O34: 0 | P34: 0
B35: =B19 -> 0 | D35: =D19 -> 0 | E35: 3 | G35: 1 | I35: =IFERROR(G35/E35,"0") -> 0.33333333 | J35: 2800 | K35: 1 | L35: 0 | M35: 0 | N35: =IFERROR(M35/L35,"0") -> 0 | O35: 0 | P35: 0
B36: =B20 -> 0 | D36: =D20 -> 0 | E36: 0 | G36: 0 | I36: =IFERROR(G36/E36,"0") -> 0 | N36: =IFERROR(M36/L36,"0") -> 0
B37: =B21 -> 0 | D37: =D21 -> 0 | I37: =IFERROR(G37/E37,"0") -> 0 | N37: =IFERROR(M37/L37,"0") -> 0
B38: =B22 -> 0 | D38: =D22 -> 0 | I38: =IFERROR(G38/E38,"0") -> 0 | N38: =IFERROR(M38/L38,"0") -> 0
B39: =B23 -> 0 | D39: =D23 -> 0 | I39: =IFERROR(G39/E39,"0") -> 0 | N39: =IFERROR(M39/L39,"0") -> 0
B40: =B24 -> 0 | D40: =D24 -> 0 | I40: =IFERROR(G40/E40,"0") -> 0 | N40: =IFERROR(M40/L40,"0") -> 0
B41: TOTAL | D41: =SUM(D33:D40) -> 10 | E41: =SUM(E33:E40) -> 13 | F41: =SUM(F33:F40) -> 0 | G41: =SUM(G33:G40) -> 3 | H41: =SUM(H33:H40) -> 0 | I41: =IFERROR(G41/E41,"0") -> 0.23076923 | J41: =SUM(J33:J40) -> 25600 | K41: =SUM(K33:K40) -> 4 | L41: =SUM(L33:L40) -> 4 | M41: =SUM(M33:M40) -> 1 | N41: =IFERROR(M41/L41,"0") -> 0.25 | O41: =SUM(O33:O40) -> 1 | P41: =SUM(P33:P40) -> 1

Sheet PLAN.ACCIÓN_D
B1: ENFOQUE DIARIO! - Nuestro plan de acción | H1: Semana: | J1: Día: | O1: LAS CELDAS EN COLOR VERDE SE LLENAN AUTOMÁTICAMENTE
A2: ¿QÚE ESPERAMOS PARA EL DÍA DE HOY?
B4: HORAS PROGRAMADAS | C4: META (NS) | D4: META PIEZAS | E4: META (NS) PRODUCTIVIDAD | F4: META UNIDADES PRODUCTIVIDAD | I4: ¿Cuál debe ser nuestro ritmo de venta hoy?
B5: =DOMINGO!D25 -> 10 | C5: =DOMINGO!C5 -> 4758 | D5: =DOMINGO!C8 -> 1.0305393 | E5: =DOMINGO!M5 -> 475.8 | F5: =DOMINGO!M6 -> 0.10305393
B7: NUESTROS ESTÁNDARES | I7: NUESTROS NO NEGOCIABLES
B9: LIMPIEZA DE LA TIENDA Barre, limpia y desinfecta. Asegúrate de que la tienda luzca impecable. Pon especial atención al piso de ventas, aparadores, espejos, mobiliario, puerta de acceso, baño y almacén. | I9: RECORDATORIO DE ENTRADA Y SALIDA Al iniciar el día, recuerda al equipo registrar su entrada y, al finalizar su turno, registrar su salida. La precisión de estos registros impacta directamente en los indicadores de productividad.
B10: IMAGEN PERSONAL Somos embajadores de la marca, por lo que nuestra imagen debe reflejar los valores de Sunglass Hut. | I10: SIN USO DE TELÉFONOS CELULARES Evita el uso del teléfono personal durante la jornada laboral. La navegación, publicaciones y mensajes personales deben realizarse fuera del horario de trabajo.
B11: REÚNETE CON EL EQUIPO La junta matutina es clave para tener un gran día. Asegúrate de comunicar: Cómo vamos en la semana y en el mes. La meta del día y las acciones clave para alcanzarla. | I11: MANTENTE FUERA DE LA CAJA Y RESPETA TU ZONA (si aplica) A menos que estés realizando una venta en caja, evita permanecer detrás del mostrador. Si tienes una zona asignada, respétala. Mantén una actitud positiva y utiliza tu energía para atraer clientes a la tienda.
I12: EL SEGUIMIENTO ES FUNDAMENTAL Durante todo el día da seguimiento al desempeño de cada colaborador. El Store Dashboard es la principal herramienta para monitorear resultados, impulsar el desempeño y reaccionar oportunamente cuando las ventas sean lentas.
B14: LOS CINCO SECRETOS / BRANDIES | I14: CUSTOMER JOURNEY
B16: PULIR ES PODER Tu paño de limpieza es una herramienta para generar conexión con el cliente y demostrar el valor del producto. Ofrece limpiar sus lentes al iniciar la conversación para crear una experiencia positiva desde el primer contacto. | I16: EMPIEZA UNA RELACION | L16: GÁNATE SU CONFIANZA | O16: GANA LEALTAD
B17: PÓNTELOS Cuando el cliente se prueba los productos, aumenta su interés y la intención de compra. Utiliza la bandeja de exhibición para ayudarle a comparar opciones e invítalo a probar diferentes modelos hasta encontrar el ideal. | I17: INTERACTÚA Y RELACIONA | L17: DESCUBRE Y APRENDE | O17: VE MÁS ALLÁ
B18: DIVIÉRTETE MÁS La venta no termina con el primer par. Aprovecha la oportunidad para mostrar tres o cuatro opciones adicionales y aumentar las posibilidades de realizar una venta múltiple. | I18: Da la bienvenida genuinamente. | L18: Identifica necesidades (emocional/racional). | O18: Guía la compra con preguntas cerradas.
B19: CUIDALOS Enseñar al cliente cómo cuidar sus lentes mejora su experiencia y fortalece tu papel como asesor especializado. | I19: Observa al cliente y adapta tu acercamiento. | L19: Haz preguntas abiertas, escucha. | O19: Propón formas de pago alternativas.
B20: AJUSTE PERFECTO Un cliente se siente mucho más satisfecho cuando sus lentes quedan perfectamente ajustados. Dedica el tiempo necesario para lograr un ajuste cómodo y personalizado. | I20: Ofrécete a limpiar y ajustar sus gafas. | L20: Recomienda múltiples. | O20: Demuestra que te preocupas, explica cómo cuidar su compra y vuelve a ofrecer Care Kits.
I21: Descubre el próposito de la visita. | L21: Presenta las características como beneficios. | O21: Registra sus datos para el programa de lealtad.
I22: Presenta Wearables, Smart Shopper y las novedades. | L22: Comparte tu experiencia en formas y estilos. Aprovecha promociones y realiza venta adicional (Cross Selling). | O22: Invítalo a compartir su experiencia de compra mediante la encuesta (NPS).
L23: Ofrece Care Kits. | O23: Invítalo a regresar para futuras compras y seguimiento a posibles garantías.
L24: Gestiona las objeciones como oportunidades.
A26: TU ENFOQUE PARA HOY
A29: LOGROS DE HOY Y OPORTUNIDADES PARA MAÑANA

Sheet LUNES
C1: ENFOQUE DIARIO! - Nuestra meta | H1: Semana: | I1: 29 | J1: Día: | L1: Tienda: | M1: GG5 | P1: LAS CELDAS EN COLOR VERDE SE LLENAN AUTOMÁTICAMENTE
A2: ¿QÚE ESPERAMOS LOGRAR HOY?
B4: META DEL DÍA | E4: CONVERSIÓN (NO NEGOCIABLE) | H4: OTROS NO NEGOCIABLES | J4: UNIDADES | L4: META DE PRODUCTIVIDAD | P4: CAPTURA LOS VALORES DEL DÍA COMP
B5: META DIARIA | E5: TRÁFICO ESPERADO | H5: WEARABLES | I5: 0.15 | J5: =IF(C7/8100<1,1,C7/8100) -> 1 | L5: VENTA NETA (NS) | M5: =C5/D25 -> 0
B6: ANÁLOGOS | C6: =C5*0.85 -> 0 | E6: META DE CONVERSIÓN (LY+1P.P) | H6: KIDS | I6: 0.05 | J6: =IF(+C8*I6<1,1,C8*I6) -> #DIV/0! | L6: UNIDADES | M6: =C8/D25 -> #DIV/0! | P6: ATV
B7: WEARABLES | C7: =+C5*0.15 -> 0 | E7: META TRANSACCIONES | F7: =+F5*F6 -> 0 | H7: CAREKITS | I7: 0.3 | J7: =IF(C8*I7<1,1,C8*I7) -> #DIV/0!
B8: TOTAL DE UNIDADES | C8: =+C5/P9 -> #DIV/0! | E8: META IDEAL (NS)* | F8: =+C5*1.1 -> 0 | I8: *Si las unidades dan como resultado menor a cero, el objetivo será mínimo una unidad. | L8: COMP LY | P8: AUR
E9: *Si tienes adeudo en la semana puedes ajustar la meta ideal | L9: VENTA NETA LY (NS)
P10: CAPTURA LOS VALORES ACUMULADOS DEL MES (MTD)
C11: APERTURA-1pm | D11: 1pm - 3pm | E11: 3pm-5pm | F11: 5pm-7pm | G11: 7pm-CIERRE | H11: TOTAL
B12: TRÁFICO POR HORA | H12: =SUM(C12:G12) -> 0 | P12: ATV
B13: PESO DEL TRÁFICO (%) | C13: =+C12/$H$12 -> #DIV/0! | D13: =+D12/$H$12 -> #DIV/0! | E13: =+E12/$H$12 -> #DIV/0! | F13: =+F12/$H$12 -> #DIV/0! | G13: =+G12/$H$12 -> #DIV/0!
B14: META (NS) X HORA | C14: =+C13*$C$5 -> #DIV/0! | D14: =+D13*$C$5 -> #DIV/0! | E14: =+E13*$C$5 -> #DIV/0! | F14: =+F13*$C$5 -> #DIV/0! | G14: =+G13*$C$5 -> #DIV/0! | H14: =+SUM(C14:G14) -> #DIV/0! | P14: AUR
B16: COLABORADORES | D16: HORAS PROGRAMADAS | E16: META DE VENTA | F16: ANALOGOS POR VENDER | G16: WEARABLES POR VENDER | H16: KIDS POR VENDER | I16: CK POR VENDER | L16: Además de cumplir con la meta diaria de la tienda para los No Negociables, cada colaborador debe procurar vender durante su turno al menos: 1 armazón Kids 1 CareKit
B17: ELIAS | D17: 3.5 | E17: =($C$5/$D$25)*D17 -> 0 | F17: =IF((($C$8-$J$5)/$D$25)*D17<1,1,((($C$8-$J$5)/$D$25)*D17)) -> #DIV/0! | H17: =IF(D17>0,MAX(($J$6/$D$25)*D17,1),0) -> #DIV/0! | I17: =IF(D17>0,MAX(($J$7/$D$25)*D17,1),0) -> #DIV/0!
B18: CATALINA | D18: 7 | E18: =($C$5/$D$25)*D18 -> 0 | F18: =IF((($C$8-$J$5)/$D$25)*D18<1,1,((($C$8-$J$5)/$D$25)*D18)) -> #DIV/0! | H18: =IF(D18>0,MAX(($J$6/$D$25)*D18,1),0) -> #DIV/0! | I18: =IF(D18>0,MAX(($J$7/$D$25)*D18,1),0) -> #DIV/0!
B19: VICTOR | D19: 7 | E19: =($C$5/$D$25)*D19 -> 0 | F19: =IF((($C$8-$J$5)/$D$25)*D19<1,1,((($C$8-$J$5)/$D$25)*D19)) -> #DIV/0! | H19: =IF(D19>0,MAX(($J$6/$D$25)*D19,1),0) -> #DIV/0! | I19: =IF(D19>0,MAX(($J$7/$D$25)*D19,1),0) -> #DIV/0!
B20: JIMENA | D20: 7 | E20: =($C$5/$D$25)*D20 -> 0 | F20: =IF((($C$8-$J$5)/$D$25)*D20<1,1,((($C$8-$J$5)/$D$25)*D20)) -> #DIV/0! | H20: =IF(D20>0,MAX(($J$6/$D$25)*D20,1),0) -> #DIV/0! | I20: =IF(D20>0,MAX(($J$7/$D$25)*D20,1),0) -> #DIV/0!
E21: =($C$5/$D$25)*D21 -> 0 | F21: =IF((($C$8-$J$5)/$D$25)*D21<1,1,((($C$8-$J$5)/$D$25)*D21)) -> #DIV/0! | H21: =IF(D21>0,MAX(($J$6/$D$25)*D21,1),0) -> 0 | I21: =IF(D21>0,MAX(($J$7/$D$25)*D21,1),0) -> 0
E22: =($C$5/$D$25)*D22 -> 0 | F22: =IF((($C$8-$J$5)/$D$25)*D22<1,1,((($C$8-$J$5)/$D$25)*D22)) -> #DIV/0! | H22: =IF(D22>0,MAX(($J$6/$D$25)*D22,1),0) -> 0 | I22: =IF(D22>0,MAX(($J$7/$D$25)*D22,1),0) -> 0
E23: =($C$5/$D$25)*D23 -> 0 | F23: =IF((($C$8-$J$5)/$D$25)*D23<1,1,((($C$8-$J$5)/$D$25)*D23)) -> #DIV/0! | H23: =IF(D23>0,MAX(($J$6/$D$25)*D23,1),0) -> 0 | I23: =IF(D23>0,MAX(($J$7/$D$25)*D23,1),0) -> 0
E24: =($C$5/$D$25)*D24 -> 0 | F24: =IF((($C$8-$J$5)/$D$25)*D24<1,1,((($C$8-$J$5)/$D$25)*D24)) -> #DIV/0! | H24: =IF(D24>0,MAX(($J$6/$D$25)*D24,1),0) -> 0 | I24: =IF(D24>0,MAX(($J$7/$D$25)*D24,1),0) -> 0
B25: TOTAL | C25: TOTAL | D25: =+SUM(D17:D24) -> 24.5 | E25: =SUM(E17:E24) -> 0 | F25: =SUM(F17:F24) -> #DIV/0! | G25: =SUM(G17:G24) -> 0 | H25: =+J6 -> #DIV/0! | I25: =+J7 -> #DIV/0!
A27: ¿CÓMO VAMOS?
D29: META | E29: VENTA NETA | F29: META UNIDADES | G29: VENTA UNIDADES | H29: CONVERSION (%) | I29: CRECIMIENTO CONVERSION (%) | J29: WEARABLES % | K29: KIDS% | L29: CAREKITS% | M29: SLP | O29: ONESIGHT
B30: TOTAL DEL DÍA | C30: TOTAL | D30: =+C5 -> 0 | E30: 25600 | F30: =+C8 -> #DIV/0! | G30: 5 | H30: =G41/E41 -> #DIV/0! | I30: =H30-F6 -> #DIV/0! | J30: 0.316 | K30: 0.111 | L30: =P41/G30 -> 0
B32: COLABORADOR | D32: HORAS PROGRAMADAS | E32: INTERACCIONES DURANTE EL DÍA | G32: CLIENTES CONVERTIDOS DURANTE EL DÍA | I32: CONVERSION AL CIERRE | J32: VENTA NETA AL CIERRE | K32: UNIDADES ANALOGAS AL CIERRE | L32: DEMOSTRACIONES WEARABLES AL CIERRE | M32: UNIDADES WEARABLES AL CIERRE | N32: CONVERSION WEREABLE | O32: KIDS AL CIERRE | P32: CAREKITS AL CIERRE | Q32: SLP EOD
B33: =B17 -> ELIAS | D33: =D17 -> 3.5 | I33: =IFERROR(G33/E33,"0") -> 0 | N33: =IFERROR(M33/L33,"0") -> 0
B34: =B18 -> CATALINA | D34: =D18 -> 7 | I34: =IFERROR(G34/E34,"0") -> 0 | N34: =IFERROR(M34/L34,"0") -> 0
B35: =B19 -> VICTOR | D35: =D19 -> 7 | I35: =IFERROR(G35/E35,"0") -> 0 | N35: =IFERROR(M35/L35,"0") -> 0
B36: =B20 -> JIMENA | D36: =D20 -> 7 | I36: =IFERROR(G36/E36,"0") -> 0 | N36: =IFERROR(M36/L36,"0") -> 0
B37: =B21 -> 0 | D37: =D21 -> 0 | I37: =IFERROR(G37/E37,"0") -> 0 | N37: =IFERROR(M37/L37,"0") -> 0
B38: =B22 -> 0 | D38: =D22 -> 0 | I38: =IFERROR(G38/E38,"0") -> 0 | N38: =IFERROR(M38/L38,"0") -> 0
B39: =B23 -> 0 | D39: =D23 -> 0 | I39: =IFERROR(G39/E39,"0") -> 0 | N39: =IFERROR(M39/L39,"0") -> 0
B40: =B24 -> 0 | D40: =D24 -> 0 | I40: =IFERROR(G40/E40,"0") -> 0 | N40: =IFERROR(M40/L40,"0") -> 0
B41: TOTAL | D41: =SUM(D33:D40) -> 24.5 | E41: =SUM(E33:E40) -> 0 | F41: =SUM(F33:F40) -> 0 | G41: =SUM(G33:G40) -> 0 | H41: =SUM(H33:H40) -> 0 | I41: =IFERROR(G41/E41,"0") -> 0 | J41: =SUM(J33:J40) -> 0 | K41: =SUM(K33:K40) -> 0 | L41: =SUM(L33:L40) -> 0 | M41: =SUM(M33:M40) -> 0 | N41: =IFERROR(M41/L41,"0") -> 0 | O41: =SUM(O33:O40) -> 0 | P41: =SUM(P33:P40) -> 0

Sheet PLAN.ACCIÓN_L
B1: ENFOQUE DIARIO! - Nuestro plan de acción | H1: Semana: | J1: Día: | O1: LAS CELDAS EN COLOR VERDE SE LLENAN AUTOMÁTICAMENTE
A2: ¿QÚE ESPERAMOS PARA EL DÍA DE HOY?
B4: HORAS PROGRAMADAS | C4: META (NS) | D4: META PIEZAS | E4: META (NS) PRODUCTIVIDAD | F4: META UNIDADES PRODUCTIVIDAD | I4: ¿Cuál debe ser nuestro ritmo de venta hoy?
B5: =DOMINGO!D25 -> 10 | C5: =DOMINGO!C5 -> 4758 | D5: =DOMINGO!C8 -> 1.0305393 | E5: =DOMINGO!M5 -> 475.8 | F5: =DOMINGO!M6 -> 0.10305393
B7: NUESTROS ESTÁNDARES | I7: NUESTROS NO NEGOCIABLES
B9: LIMPIEZA DE LA TIENDA Barre, limpia y desinfecta. Asegúrate de que la tienda luzca impecable. Pon especial atención al piso de ventas, aparadores, espejos, mobiliario, puerta de acceso, baño y almacén. | I9: RECORDATORIO DE ENTRADA Y SALIDA Al iniciar el día, recuerda al equipo registrar su entrada y, al finalizar su turno, registrar su salida. La precisión de estos registros impacta directamente en los indicadores de productividad.
B10: IMAGEN PERSONAL Somos embajadores de la marca, por lo que nuestra imagen debe reflejar los valores de Sunglass Hut. | I10: SIN USO DE TELÉFONOS CELULARES Evita el uso del teléfono personal durante la jornada laboral. La navegación, publicaciones y mensajes personales deben realizarse fuera del horario de trabajo.
B11: REÚNETE CON EL EQUIPO La junta matutina es clave para tener un gran día. Asegúrate de comunicar: Cómo vamos en la semana y en el mes. La meta del día y las acciones clave para alcanzarla. | I11: MANTENTE FUERA DE LA CAJA Y RESPETA TU ZONA (si aplica) A menos que estés realizando una venta en caja, evita permanecer detrás del mostrador. Si tienes una zona asignada, respétala. Mantén una actitud positiva y utiliza tu energía para atraer clientes a la tienda.
I12: EL SEGUIMIENTO ES FUNDAMENTAL Durante todo el día da seguimiento al desempeño de cada colaborador. El Store Dashboard es la principal herramienta para monitorear resultados, impulsar el desempeño y reaccionar oportunamente cuando las ventas sean lentas.
B14: LOS CINCO SECRETOS / BRANDIES | I14: CUSTOMER JOURNEY
B16: PULIR ES PODER Tu paño de limpieza es una herramienta para generar conexión con el cliente y demostrar el valor del producto. Ofrece limpiar sus lentes al iniciar la conversación para crear una experiencia positiva desde el primer contacto. | I16: EMPIEZA UNA RELACION | L16: GÁNATE SU CONFIANZA | O16: GANA LEALTAD
B17: PÓNTELOS Cuando el cliente se prueba los productos, aumenta su interés y la intención de compra. Utiliza la bandeja de exhibición para ayudarle a comparar opciones e invítalo a probar diferentes modelos hasta encontrar el ideal. | I17: INTERACTÚA Y RELACIONA | L17: DESCUBRE Y APRENDE | O17: VE MÁS ALLÁ
B18: DIVIÉRTETE MÁS La venta no termina con el primer par. Aprovecha la oportunidad para mostrar tres o cuatro opciones adicionales y aumentar las posibilidades de realizar una venta múltiple. | I18: Da la bienvenida genuinamente. | L18: Identifica necesidades (emocional/racional). | O18: Guía la compra con preguntas cerradas.
B19: CUIDALOS Enseñar al cliente cómo cuidar sus lentes mejora su experiencia y fortalece tu papel como asesor especializado. | I19: Observa al cliente y adapta tu acercamiento. | L19: Haz preguntas abiertas, escucha. | O19: Propón formas de pago alternativas.
B20: AJUSTE PERFECTO Un cliente se siente mucho más satisfecho cuando sus lentes quedan perfectamente ajustados. Dedica el tiempo necesario para lograr un ajuste cómodo y personalizado. | I20: Ofrécete a limpiar y ajustar sus gafas. | L20: Recomienda múltiples. | O20: Demuestra que te preocupas, explica cómo cuidar su compra y vuelve a ofrecer Care Kits.
I21: Descubre el próposito de la visita. | L21: Presenta las características como beneficios. | O21: Registra sus datos para el programa de lealtad.
I22: Presenta Wearables, Smart Shopper y las novedades. | L22: Comparte tu experiencia en formas y estilos. Aprovecha promociones y realiza venta adicional (Cross Selling). | O22: Invítalo a compartir su experiencia de compra mediante la encuesta (NPS).
L23: Ofrece Care Kits. | O23: Invítalo a regresar para futuras compras y seguimiento a posibles garantías.
L24: Gestiona las objeciones como oportunidades.
A26: TU ENFOQUE PARA HOY
A29: LOGROS DE HOY Y OPORTUNIDADES PARA MAÑANA

Sheet MARTES
C1: ENFOQUE DIARIO! - Nuestra meta | H1: Semana: | I1: 29 | J1: Día: | L1: Tienda: | M1: GG5 | P1: LAS CELDAS EN COLOR VERDE SE LLENAN AUTOMÁTICAMENTE
A2: ¿QÚE ESPERAMOS LOGRAR HOY?
B4: META DEL DÍA | E4: CONVERSIÓN (NO NEGOCIABLE) | H4: OTROS NO NEGOCIABLES | J4: UNIDADES | L4: META DE PRODUCTIVIDAD | P4: CAPTURA LOS VALORES DEL DÍA COMP
B5: META DIARIA | E5: TRÁFICO ESPERADO | H5: WEARABLES | I5: 0.15 | J5: =IF(C7/8100<1,1,C7/8100) -> 1 | L5: VENTA NETA (NS) | M5: =C5/D25 -> 0
B6: ANÁLOGOS | C6: =C5*0.85 -> 0 | E6: META DE CONVERSIÓN (LY+1P.P) | H6: KIDS | I6: 0.05 | J6: =IF(+C8*I6<1,1,C8*I6) -> #DIV/0! | L6: UNIDADES | M6: =C8/D25 -> #DIV/0! | P6: ATV
B7: WEARABLES | C7: =+C5*0.15 -> 0 | E7: META TRANSACCIONES | F7: =+F5*F6 -> 0 | H7: CAREKITS | I7: 0.3 | J7: =IF(C8*I7<1,1,C8*I7) -> #DIV/0!
B8: TOTAL DE UNIDADES | C8: =+C5/P9 -> #DIV/0! | E8: META IDEAL (NS)* | F8: =+C5*1.1 -> 0 | I8: *Si las unidades dan como resultado menor a cero, el objetivo será mínimo una unidad. | L8: COMP LY | P8: AUR
E9: *Si tienes adeudo en la semana puedes ajustar la meta ideal | L9: VENTA NETA LY (NS)
P10: CAPTURA LOS VALORES ACUMULADOS DEL MES (MTD)
C11: APERTURA-1pm | D11: 1pm - 3pm | E11: 3pm-5pm | F11: 5pm-7pm | G11: 7pm-CIERRE | H11: TOTAL
B12: TRÁFICO POR HORA | H12: =SUM(C12:G12) -> 0 | P12: ATV
B13: PESO DEL TRÁFICO (%) | C13: =+C12/$H$12 -> #DIV/0! | D13: =+D12/$H$12 -> #DIV/0! | E13: =+E12/$H$12 -> #DIV/0! | F13: =+F12/$H$12 -> #DIV/0! | G13: =+G12/$H$12 -> #DIV/0!
B14: META (NS) X HORA | C14: =+C13*$C$5 -> #DIV/0! | D14: =+D13*$C$5 -> #DIV/0! | E14: =+E13*$C$5 -> #DIV/0! | F14: =+F13*$C$5 -> #DIV/0! | G14: =+G13*$C$5 -> #DIV/0! | H14: =+SUM(C14:G14) -> #DIV/0! | P14: AUR
B16: COLABORADORES | D16: HORAS PROGRAMADAS | E16: META DE VENTA | F16: ANALOGOS POR VENDER | G16: WEARABLES POR VENDER | H16: KIDS POR VENDER | I16: CK POR VENDER | L16: Además de cumplir con la meta diaria de la tienda para los No Negociables, cada colaborador debe procurar vender durante su turno al menos: 1 armazón Kids 1 CareKit
B17: ELIAS | D17: 3.5 | E17: =($C$5/$D$25)*D17 -> 0 | F17: =IF((($C$8-$J$5)/$D$25)*D17<1,1,((($C$8-$J$5)/$D$25)*D17)) -> #DIV/0! | H17: =IF(D17>0,MAX(($J$6/$D$25)*D17,1),0) -> #DIV/0! | I17: =IF(D17>0,MAX(($J$7/$D$25)*D17,1),0) -> #DIV/0!
B18: CATALINA | D18: 7 | E18: =($C$5/$D$25)*D18 -> 0 | F18: =IF((($C$8-$J$5)/$D$25)*D18<1,1,((($C$8-$J$5)/$D$25)*D18)) -> #DIV/0! | H18: =IF(D18>0,MAX(($J$6/$D$25)*D18,1),0) -> #DIV/0! | I18: =IF(D18>0,MAX(($J$7/$D$25)*D18,1),0) -> #DIV/0!
B19: VICTOR | D19: 7 | E19: =($C$5/$D$25)*D19 -> 0 | F19: =IF((($C$8-$J$5)/$D$25)*D19<1,1,((($C$8-$J$5)/$D$25)*D19)) -> #DIV/0! | H19: =IF(D19>0,MAX(($J$6/$D$25)*D19,1),0) -> #DIV/0! | I19: =IF(D19>0,MAX(($J$7/$D$25)*D19,1),0) -> #DIV/0!
B20: JIMENA | D20: 7 | E20: =($C$5/$D$25)*D20 -> 0 | F20: =IF((($C$8-$J$5)/$D$25)*D20<1,1,((($C$8-$J$5)/$D$25)*D20)) -> #DIV/0! | H20: =IF(D20>0,MAX(($J$6/$D$25)*D20,1),0) -> #DIV/0! | I20: =IF(D20>0,MAX(($J$7/$D$25)*D20,1),0) -> #DIV/0!
E21: =($C$5/$D$25)*D21 -> 0 | F21: =IF((($C$8-$J$5)/$D$25)*D21<1,1,((($C$8-$J$5)/$D$25)*D21)) -> #DIV/0! | H21: =IF(D21>0,MAX(($J$6/$D$25)*D21,1),0) -> 0 | I21: =IF(D21>0,MAX(($J$7/$D$25)*D21,1),0) -> 0
E22: =($C$5/$D$25)*D22 -> 0 | F22: =IF((($C$8-$J$5)/$D$25)*D22<1,1,((($C$8-$J$5)/$D$25)*D22)) -> #DIV/0! | H22: =IF(D22>0,MAX(($J$6/$D$25)*D22,1),0) -> 0 | I22: =IF(D22>0,MAX(($J$7/$D$25)*D22,1),0) -> 0
E23: =($C$5/$D$25)*D23 -> 0 | F23: =IF((($C$8-$J$5)/$D$25)*D23<1,1,((($C$8-$J$5)/$D$25)*D23)) -> #DIV/0! | H23: =IF(D23>0,MAX(($J$6/$D$25)*D23,1),0) -> 0 | I23: =IF(D23>0,MAX(($J$7/$D$25)*D23,1),0) -> 0
E24: =($C$5/$D$25)*D24 -> 0 | F24: =IF((($C$8-$J$5)/$D$25)*D24<1,1,((($C$8-$J$5)/$D$25)*D24)) -> #DIV/0! | H24: =IF(D24>0,MAX(($J$6/$D$25)*D24,1),0) -> 0 | I24: =IF(D24>0,MAX(($J$7/$D$25)*D24,1),0) -> 0
B25: TOTAL | C25: TOTAL | D25: =+SUM(D17:D24) -> 24.5 | E25: =SUM(E17:E24) -> 0 | F25: =SUM(F17:F24) -> #DIV/0! | G25: =SUM(G17:G24) -> 0 | H25: =+J6 -> #DIV/0! | I25: =+J7 -> #DIV/0!
A27: ¿CÓMO VAMOS?
D29: META | E29: VENTA NETA | F29: META UNIDADES | G29: VENTA UNIDADES | H29: CONVERSION (%) | I29: CRECIMIENTO CONVERSION (%) | J29: WEARABLES % | K29: KIDS% | L29: CAREKITS% | M29: SLP | O29: ONESIGHT
B30: TOTAL DEL DÍA | C30: TOTAL | D30: =+C5 -> 0 | E30: 25600 | F30: =+C8 -> #DIV/0! | G30: 5 | H30: =G41/E41 -> #DIV/0! | I30: =H30-F6 -> #DIV/0! | J30: 0.316 | K30: 0.111 | L30: =P41/G30 -> 0
B32: COLABORADOR | D32: HORAS PROGRAMADAS | E32: INTERACCIONES DURANTE EL DÍA | G32: CLIENTES CONVERTIDOS DURANTE EL DÍA | I32: CONVERSION AL CIERRE | J32: VENTA NETA AL CIERRE | K32: UNIDADES ANALOGAS AL CIERRE | L32: DEMOSTRACIONES WEARABLES AL CIERRE | M32: UNIDADES WEARABLES AL CIERRE | N32: CONVERSION WEREABLE | O32: KIDS AL CIERRE | P32: CAREKITS AL CIERRE | Q32: SLP EOD
B33: =B17 -> ELIAS | D33: =D17 -> 3.5 | I33: =IFERROR(G33/E33,"0") -> 0 | N33: =IFERROR(M33/L33,"0") -> 0
B34: =B18 -> CATALINA | D34: =D18 -> 7 | I34: =IFERROR(G34/E34,"0") -> 0 | N34: =IFERROR(M34/L34,"0") -> 0
B35: =B19 -> VICTOR | D35: =D19 -> 7 | I35: =IFERROR(G35/E35,"0") -> 0 | N35: =IFERROR(M35/L35,"0") -> 0
B36: =B20 -> JIMENA | D36: =D20 -> 7 | I36: =IFERROR(G36/E36,"0") -> 0 | N36: =IFERROR(M36/L36,"0") -> 0
B37: =B21 -> 0 | D37: =D21 -> 0 | I37: =IFERROR(G37/E37,"0") -> 0 | N37: =IFERROR(M37/L37,"0") -> 0
B38: =B22 -> 0 | D38: =D22 -> 0 | I38: =IFERROR(G38/E38,"0") -> 0 | N38: =IFERROR(M38/L38,"0") -> 0
B39: =B23 -> 0 | D39: =D23 -> 0 | I39: =IFERROR(G39/E39,"0") -> 0 | N39: =IFERROR(M39/L39,"0") -> 0
B40: =B24 -> 0 | D40: =D24 -> 0 | I40: =IFERROR(G40/E40,"0") -> 0 | N40: =IFERROR(M40/L40,"0") -> 0
B41: TOTAL | D41: =SUM(D33:D40) -> 24.5 | E41: =SUM(E33:E40) -> 0 | F41: =SUM(F33:F40) -> 0 | G41: =SUM(G33:G40) -> 0 | H41: =SUM(H33:H40) -> 0 | I41: =IFERROR(G41/E41,"0") -> 0 | J41: =SUM(J33:J40) -> 0 | K41: =SUM(K33:K40) -> 0 | L41: =SUM(L33:L40) -> 0 | M41: =SUM(M33:M40) -> 0 | N41: =IFERROR(M41/L41,"0") -> 0 | O41: =SUM(O33:O40) -> 0 | P41: =SUM(P33:P40) -> 0

Sheet PLAN.ACCIÓN_MA
B1: ENFOQUE DIARIO! - Nuestro plan de acción | H1: Semana: | J1: Día: | O1: LAS CELDAS EN COLOR VERDE SE LLENAN AUTOMÁTICAMENTE
A2: ¿QÚE ESPERAMOS PARA EL DÍA DE HOY?
B4: HORAS PROGRAMADAS | C4: META (NS) | D4: META PIEZAS | E4: META (NS) PRODUCTIVIDAD | F4: META UNIDADES PRODUCTIVIDAD | I4: ¿Cuál debe ser nuestro ritmo de venta hoy?
B5: =DOMINGO!D25 -> 10 | C5: =DOMINGO!C5 -> 4758 | D5: =DOMINGO!C8 -> 1.0305393 | E5: =DOMINGO!M5 -> 475.8 | F5: =DOMINGO!M6 -> 0.10305393
B7: NUESTROS ESTÁNDARES | I7: NUESTROS NO NEGOCIABLES
B9: LIMPIEZA DE LA TIENDA Barre, limpia y desinfecta. Asegúrate de que la tienda luzca impecable. Pon especial atención al piso de ventas, aparadores, espejos, mobiliario, puerta de acceso, baño y almacén. | I9: RECORDATORIO DE ENTRADA Y SALIDA Al iniciar el día, recuerda al equipo registrar su entrada y, al finalizar su turno, registrar su salida. La precisión de estos registros impacta directamente en los indicadores de productividad.
B10: IMAGEN PERSONAL Somos embajadores de la marca, por lo que nuestra imagen debe reflejar los valores de Sunglass Hut. | I10: SIN USO DE TELÉFONOS CELULARES Evita el uso del teléfono personal durante la jornada laboral. La navegación, publicaciones y mensajes personales deben realizarse fuera del horario de trabajo.
B11: REÚNETE CON EL EQUIPO La junta matutina es clave para tener un gran día. Asegúrate de comunicar: Cómo vamos en la semana y en el mes. La meta del día y las acciones clave para alcanzarla. | I11: MANTENTE FUERA DE LA CAJA Y RESPETA TU ZONA (si aplica) A menos que estés realizando una venta en caja, evita permanecer detrás del mostrador. Si tienes una zona asignada, respétala. Mantén una actitud positiva y utiliza tu energía para atraer clientes a la tienda.
I12: EL SEGUIMIENTO ES FUNDAMENTAL Durante todo el día da seguimiento al desempeño de cada colaborador. El Store Dashboard es la principal herramienta para monitorear resultados, impulsar el desempeño y reaccionar oportunamente cuando las ventas sean lentas.
B14: LOS CINCO SECRETOS / BRANDIES | I14: CUSTOMER JOURNEY
B16: PULIR ES PODER Tu paño de limpieza es una herramienta para generar conexión con el cliente y demostrar el valor del producto. Ofrece limpiar sus lentes al iniciar la conversación para crear una experiencia positiva desde el primer contacto. | I16: EMPIEZA UNA RELACION | L16: GÁNATE SU CONFIANZA | O16: GANA LEALTAD
B17: PÓNTELOS Cuando el cliente se prueba los productos, aumenta su interés y la intención de compra. Utiliza la bandeja de exhibición para ayudarle a comparar opciones e invítalo a probar diferentes modelos hasta encontrar el ideal. | I17: INTERACTÚA Y RELACIONA | L17: DESCUBRE Y APRENDE | O17: VE MÁS ALLÁ
B18: DIVIÉRTETE MÁS La venta no termina con el primer par. Aprovecha la oportunidad para mostrar tres o cuatro opciones adicionales y aumentar las posibilidades de realizar una venta múltiple. | I18: Da la bienvenida genuinamente. | L18: Identifica necesidades (emocional/racional). | O18: Guía la compra con preguntas cerradas.
B19: CUIDALOS Enseñar al cliente cómo cuidar sus lentes mejora su experiencia y fortalece tu papel como asesor especializado. | I19: Observa al cliente y adapta tu acercamiento. | L19: Haz preguntas abiertas, escucha. | O19: Propón formas de pago alternativas.
B20: AJUSTE PERFECTO Un cliente se siente mucho más satisfecho cuando sus lentes quedan perfectamente ajustados. Dedica el tiempo necesario para lograr un ajuste cómodo y personalizado. | I20: Ofrécete a limpiar y ajustar sus gafas. | L20: Recomienda múltiples. | O20: Demuestra que te preocupas, explica cómo cuidar su compra y vuelve a ofrecer Care Kits.
I21: Descubre el próposito de la visita. | L21: Presenta las características como beneficios. | O21: Registra sus datos para el programa de lealtad.
I22: Presenta Wearables, Smart Shopper y las novedades. | L22: Comparte tu experiencia en formas y estilos. Aprovecha promociones y realiza venta adicional (Cross Selling). | O22: Invítalo a compartir su experiencia de compra mediante la encuesta (NPS).
L23: Ofrece Care Kits. | O23: Invítalo a regresar para futuras compras y seguimiento a posibles garantías.
L24: Gestiona las objeciones como oportunidades.
A26: TU ENFOQUE PARA HOY
A29: LOGROS DE HOY Y OPORTUNIDADES PARA MAÑANA

Sheet MIÉRCOLES
C1: ENFOQUE DIARIO! - Nuestra meta | H1: Semana: | I1: 30 | J1: Día: | K1: 46239 | L1: Tienda: | M1: VALLEJO | P1: LAS CELDAS EN COLOR VERDE SE LLENAN AUTOMÁTICAMENTE
A2: ¿QÚE ESPERAMOS LOGRAR HOY?
B4: META DEL DÍA | E4: CONVERSIÓN (NO NEGOCIABLE) | H4: OTROS NO NEGOCIABLES | J4: UNIDADES | L4: META DE PRODUCTIVIDAD | P4: CAPTURA LOS VALORES DEL DÍA COMP
B5: META DIARIA | C5: 4758 | E5: TRÁFICO ESPERADO | F5: 8 | H5: WEARABLES | I5: 0.15 | J5: =IF(C7/8100<1,1,C7/8100) -> 1 | L5: VENTA NETA (NS) | M5: =C5/D25 -> 475.8
B6: ANÁLOGOS | C6: =C5*0.85 -> 4044.3 | E6: META DE CONVERSIÓN (LY+1P.P) | F6: 0.13 | H6: KIDS | I6: 0.05 | J6: =IF(+C8*I6<1,1,C8*I6) -> 1 | L6: UNIDADES | M6: =C8/D25 -> 0.10575683 | P6: ATV
B7: WEARABLES | C7: =+C5*0.15 -> 713.7 | E7: META TRANSACCIONES | F7: =+F5*F6 -> 1.04 | H7: CAREKITS | I7: 0.3 | J7: =IF(C8*I7<1,1,C8*I7) -> 1 | P7: 4758
B8: TOTAL DE UNIDADES | C8: =+C5/P9 -> 1.0575683 | E8: META IDEAL (NS)* | F8: =+C5*1.1 -> 5233.8 | I8: *Si las unidades dan como resultado menor a cero, el objetivo será mínimo una unidad. | L8: COMP LY | P8: AUR
E9: *Si tienes adeudo en la semana puedes ajustar la meta ideal | L9: VENTA NETA LY (NS) | M9: 4758 | P9: 4499
P10: CAPTURA LOS VALORES ACUMULADOS DEL MES (MTD)
C11: APERTURA-1pm | D11: 1pm - 3pm | E11: 3pm-5pm | F11: 5pm-7pm | G11: 7pm-CIERRE | H11: TOTAL
B12: TRÁFICO POR HORA | C12: 4 | D12: 2 | E12: 2 | F12: 0 | G12: 0 | H12: =SUM(C12:G12) -> 8 | P12: ATV
B13: PESO DEL TRÁFICO (%) | C13: =+C12/$H$12 -> 0.5 | D13: =+D12/$H$12 -> 0.25 | E13: =+E12/$H$12 -> 0.25 | F13: =+F12/$H$12 -> 0 | G13: =+G12/$H$12 -> 0 | P13: 7162
B14: META (NS) X HORA | C14: =+C13*$C$5 -> 2379 | D14: =+D13*$C$5 -> 1189.5 | E14: =+E13*$C$5 -> 1189.5 | F14: =+F13*$C$5 -> 0 | G14: =+G13*$C$5 -> 0 | H14: =+SUM(C14:G14) -> 4758 | P14: AUR
P15: 4712
B16: COLABORADORES | D16: HORAS PROGRAMADAS | E16: META DE VENTA | F16: ANALOGOS POR VENDER | G16: WEARABLES POR VENDER | H16: KIDS POR VENDER | I16: CK POR VENDER | L16: Además de cumplir con la meta diaria de la tienda para los No Negociables, cada colaborador debe procurar vender durante su turno al menos: 1 armazón Kids 1 CareKit
B17: VIVIANA | D17: 10 | E17: =($C$5/$D$25)*D17 -> 4758 | F17: =IF((($C$8-$J$5)/$D$25)*D17<1,1,((($C$8-$J$5)/$D$25)*D17)) -> 1 | H17: =IF(D17>0,MAX(($J$6/$D$25)*D17,1),0) -> 1 | I17: =IF(D17>0,MAX(($J$7/$D$25)*D17,1),0) -> 1
E18: =($C$5/$D$25)*D18 -> 0 | F18: =IF((($C$8-$J$5)/$D$25)*D18<1,1,((($C$8-$J$5)/$D$25)*D18)) -> 1 | H18: =IF(D18>0,MAX(($J$6/$D$25)*D18,1),0) -> 0 | I18: =IF(D18>0,MAX(($J$7/$D$25)*D18,1),0) -> 0
E19: =($C$5/$D$25)*D19 -> 0 | F19: =IF((($C$8-$J$5)/$D$25)*D19<1,1,((($C$8-$J$5)/$D$25)*D19)) -> 1 | H19: =IF(D19>0,MAX(($J$6/$D$25)*D19,1),0) -> 0 | I19: =IF(D19>0,MAX(($J$7/$D$25)*D19,1),0) -> 0
E20: =($C$5/$D$25)*D20 -> 0 | F20: =IF((($C$8-$J$5)/$D$25)*D20<1,1,((($C$8-$J$5)/$D$25)*D20)) -> 1 | H20: =IF(D20>0,MAX(($J$6/$D$25)*D20,1),0) -> 0 | I20: =IF(D20>0,MAX(($J$7/$D$25)*D20,1),0) -> 0
E21: =($C$5/$D$25)*D21 -> 0 | F21: =IF((($C$8-$J$5)/$D$25)*D21<1,1,((($C$8-$J$5)/$D$25)*D21)) -> 1 | H21: =IF(D21>0,MAX(($J$6/$D$25)*D21,1),0) -> 0 | I21: =IF(D21>0,MAX(($J$7/$D$25)*D21,1),0) -> 0
E22: =($C$5/$D$25)*D22 -> 0 | F22: =IF((($C$8-$J$5)/$D$25)*D22<1,1,((($C$8-$J$5)/$D$25)*D22)) -> 1 | H22: =IF(D22>0,MAX(($J$6/$D$25)*D22,1),0) -> 0 | I22: =IF(D22>0,MAX(($J$7/$D$25)*D22,1),0) -> 0
E23: =($C$5/$D$25)*D23 -> 0 | F23: =IF((($C$8-$J$5)/$D$25)*D23<1,1,((($C$8-$J$5)/$D$25)*D23)) -> 1 | H23: =IF(D23>0,MAX(($J$6/$D$25)*D23,1),0) -> 0 | I23: =IF(D23>0,MAX(($J$7/$D$25)*D23,1),0) -> 0
E24: =($C$5/$D$25)*D24 -> 0 | F24: =IF((($C$8-$J$5)/$D$25)*D24<1,1,((($C$8-$J$5)/$D$25)*D24)) -> 1 | H24: =IF(D24>0,MAX(($J$6/$D$25)*D24,1),0) -> 0 | I24: =IF(D24>0,MAX(($J$7/$D$25)*D24,1),0) -> 0
B25: TOTAL | C25: TOTAL | D25: =+SUM(D17:D24) -> 10 | E25: =SUM(E17:E24) -> 4758 | F25: =SUM(F17:F24) -> 8 | G25: =SUM(G17:G24) -> 0 | H25: =+J6 -> 1 | I25: =+J7 -> 1
A27: ¿CÓMO VAMOS?
D29: META | E29: VENTA NETA | F29: META UNIDADES | G29: VENTA UNIDADES | H29: CONVERSION (%) | I29: CRECIMIENTO CONVERSION (%) | J29: WEARABLES % | K29: KIDS% | L29: CAREKITS% | M29: SLP | O29: ONESIGHT
B30: TOTAL DEL DÍA | C30: TOTAL | D30: =+C5 -> 4758 | E30: 25600 | F30: =+C8 -> 1.0575683 | G30: 5 | H30: =G41/E41 -> #DIV/0! | I30: =H30-F6 -> #DIV/0! | J30: 0.316 | K30: 0.111 | L30: =P41/G30 -> 0
B32: COLABORADOR | D32: HORAS PROGRAMADAS | E32: INTERACCIONES DURANTE EL DÍA | G32: CLIENTES CONVERTIDOS DURANTE EL DÍA | I32: CONVERSION AL CIERRE | J32: VENTA NETA AL CIERRE | K32: UNIDADES ANALOGAS AL CIERRE | L32: DEMOSTRACIONES WEARABLES AL CIERRE | M32: UNIDADES WEARABLES AL CIERRE | N32: CONVERSION WEREABLE | O32: KIDS AL CIERRE | P32: CAREKITS AL CIERRE | Q32: SLP EOD
B33: =B17 -> VIVIANA | D33: =D17 -> 10 | I33: =IFERROR(G33/E33,"0") -> 0 | N33: =IFERROR(M33/L33,"0") -> 0
B34: =B18 -> 0 | D34: =D18 -> 0 | I34: =IFERROR(G34/E34,"0") -> 0 | N34: =IFERROR(M34/L34,"0") -> 0
B35: =B19 -> 0 | D35: =D19 -> 0 | I35: =IFERROR(G35/E35,"0") -> 0 | N35: =IFERROR(M35/L35,"0") -> 0
B36: =B20 -> 0 | D36: =D20 -> 0 | I36: =IFERROR(G36/E36,"0") -> 0 | N36: =IFERROR(M36/L36,"0") -> 0
B37: =B21 -> 0 | D37: =D21 -> 0 | I37: =IFERROR(G37/E37,"0") -> 0 | N37: =IFERROR(M37/L37,"0") -> 0
B38: =B22 -> 0 | D38: =D22 -> 0 | I38: =IFERROR(G38/E38,"0") -> 0 | N38: =IFERROR(M38/L38,"0") -> 0
B39: =B23 -> 0 | D39: =D23 -> 0 | I39: =IFERROR(G39/E39,"0") -> 0 | N39: =IFERROR(M39/L39,"0") -> 0
B40: =B24 -> 0 | D40: =D24 -> 0 | I40: =IFERROR(G40/E40,"0") -> 0 | N40: =IFERROR(M40/L40,"0") -> 0
B41: TOTAL | D41: =SUM(D33:D40) -> 10 | E41: =SUM(E33:E40) -> 0 | F41: =SUM(F33:F40) -> 0 | G41: =SUM(G33:G40) -> 0 | H41: =SUM(H33:H40) -> 0 | I41: =IFERROR(G41/E41,"0") -> 0 | J41: =SUM(J33:J40) -> 0 | K41: =SUM(K33:K40) -> 0 | L41: =SUM(L33:L40) -> 0 | M41: =SUM(M33:M40) -> 0 | N41: =IFERROR(M41/L41,"0") -> 0 | O41: =SUM(O33:O40) -> 0 | P41: =SUM(P33:P40) -> 0

Sheet PLAN.ACCIÓN_MI
B1: ENFOQUE DIARIO! - Nuestro plan de acción | H1: Semana: | J1: Día: | O1: LAS CELDAS EN COLOR VERDE SE LLENAN AUTOMÁTICAMENTE
A2: ¿QÚE ESPERAMOS PARA EL DÍA DE HOY?
B4: HORAS PROGRAMADAS | C4: META (NS) | D4: META PIEZAS | E4: META (NS) PRODUCTIVIDAD | F4: META UNIDADES PRODUCTIVIDAD | I4: ¿Cuál debe ser nuestro ritmo de venta hoy?
B5: =DOMINGO!D25 -> 10 | C5: =DOMINGO!C5 -> 4758 | D5: =DOMINGO!C8 -> 1.0305393 | E5: =DOMINGO!M5 -> 475.8 | F5: =DOMINGO!M6 -> 0.10305393
B7: NUESTROS ESTÁNDARES | I7: NUESTROS NO NEGOCIABLES
B9: LIMPIEZA DE LA TIENDA Barre, limpia y desinfecta. Asegúrate de que la tienda luzca impecable. Pon especial atención al piso de ventas, aparadores, espejos, mobiliario, puerta de acceso, baño y almacén. | I9: RECORDATORIO DE ENTRADA Y SALIDA Al iniciar el día, recuerda al equipo registrar su entrada y, al finalizar su turno, registrar su salida. La precisión de estos registros impacta directamente en los indicadores de productividad.
B10: IMAGEN PERSONAL Somos embajadores de la marca, por lo que nuestra imagen debe reflejar los valores de Sunglass Hut. | I10: SIN USO DE TELÉFONOS CELULARES Evita el uso del teléfono personal durante la jornada laboral. La navegación, publicaciones y mensajes personales deben realizarse fuera del horario de trabajo.
B11: REÚNETE CON EL EQUIPO La junta matutina es clave para tener un gran día. Asegúrate de comunicar: Cómo vamos en la semana y en el mes. La meta del día y las acciones clave para alcanzarla. | I11: MANTENTE FUERA DE LA CAJA Y RESPETA TU ZONA (si aplica) A menos que estés realizando una venta en caja, evita permanecer detrás del mostrador. Si tienes una zona asignada, respétala. Mantén una actitud positiva y utiliza tu energía para atraer clientes a la tienda.
I12: EL SEGUIMIENTO ES FUNDAMENTAL Durante todo el día da seguimiento al desempeño de cada colaborador. El Store Dashboard es la principal herramienta para monitorear resultados, impulsar el desempeño y reaccionar oportunamente cuando las ventas sean lentas.
B14: LOS CINCO SECRETOS / BRANDIES | I14: CUSTOMER JOURNEY
B16: PULIR ES PODER Tu paño de limpieza es una herramienta para generar conexión con el cliente y demostrar el valor del producto. Ofrece limpiar sus lentes al iniciar la conversación para crear una experiencia positiva desde el primer contacto. | I16: EMPIEZA UNA RELACION | L16: GÁNATE SU CONFIANZA | O16: GANA LEALTAD
B17: PÓNTELOS Cuando el cliente se prueba los productos, aumenta su interés y la intención de compra. Utiliza la bandeja de exhibición para ayudarle a comparar opciones e invítalo a probar diferentes modelos hasta encontrar el ideal. | I17: INTERACTÚA Y RELACIONA | L17: DESCUBRE Y APRENDE | O17: VE MÁS ALLÁ
B18: DIVIÉRTETE MÁS La venta no termina con el primer par. Aprovecha la oportunidad para mostrar tres o cuatro opciones adicionales y aumentar las posibilidades de realizar una venta múltiple. | I18: Da la bienvenida genuinamente. | L18: Identifica necesidades (emocional/racional). | O18: Guía la compra con preguntas cerradas.
B19: CUIDALOS Enseñar al cliente cómo cuidar sus lentes mejora su experiencia y fortalece tu papel como asesor especializado. | I19: Observa al cliente y adapta tu acercamiento. | L19: Haz preguntas abiertas, escucha. | O19: Propón formas de pago alternativas.
B20: AJUSTE PERFECTO Un cliente se siente mucho más satisfecho cuando sus lentes quedan perfectamente ajustados. Dedica el tiempo necesario para lograr un ajuste cómodo y personalizado. | I20: Ofrécete a limpiar y ajustar sus gafas. | L20: Recomienda múltiples. | O20: Demuestra que te preocupas, explica cómo cuidar su compra y vuelve a ofrecer Care Kits.
I21: Descubre el próposito de la visita. | L21: Presenta las características como beneficios. | O21: Registra sus datos para el programa de lealtad.
I22: Presenta Wearables, Smart Shopper y las novedades. | L22: Comparte tu experiencia en formas y estilos. Aprovecha promociones y realiza venta adicional (Cross Selling). | O22: Invítalo a compartir su experiencia de compra mediante la encuesta (NPS).
L23: Ofrece Care Kits. | O23: Invítalo a regresar para futuras compras y seguimiento a posibles garantías.
L24: Gestiona las objeciones como oportunidades.
A26: TU ENFOQUE PARA HOY
A29: LOGROS DE HOY Y OPORTUNIDADES PARA MAÑANA

Sheet JUEVES
C1: ENFOQUE DIARIO! - Nuestra meta | H1: Semana: | I1: 29 | J1: Día: | L1: Tienda: | M1: GG5 | P1: LAS CELDAS EN COLOR VERDE SE LLENAN AUTOMÁTICAMENTE
A2: ¿QÚE ESPERAMOS LOGRAR HOY?
B4: META DEL DÍA | E4: CONVERSIÓN (NO NEGOCIABLE) | H4: OTROS NO NEGOCIABLES | J4: UNIDADES | L4: META DE PRODUCTIVIDAD | P4: CAPTURA LOS VALORES DEL DÍA COMP
B5: META DIARIA | E5: TRÁFICO ESPERADO | H5: WEARABLES | I5: 0.15 | J5: =IF(C7/8100<1,1,C7/8100) -> 1 | L5: VENTA NETA (NS) | M5: =C5/D25 -> 0
B6: ANÁLOGOS | C6: =C5*0.85 -> 0 | E6: META DE CONVERSIÓN (LY+1P.P) | H6: KIDS | I6: 0.05 | J6: =IF(+C8*I6<1,1,C8*I6) -> #DIV/0! | L6: UNIDADES | M6: =C8/D25 -> #DIV/0! | P6: ATV
B7: WEARABLES | C7: =+C5*0.15 -> 0 | E7: META TRANSACCIONES | F7: =+F5*F6 -> 0 | H7: CAREKITS | I7: 0.3 | J7: =IF(C8*I7<1,1,C8*I7) -> #DIV/0!
B8: TOTAL DE UNIDADES | C8: =+C5/P9 -> #DIV/0! | E8: META IDEAL (NS)* | F8: =+C5*1.1 -> 0 | I8: *Si las unidades dan como resultado menor a cero, el objetivo será mínimo una unidad. | L8: COMP LY | P8: AUR
E9: *Si tienes adeudo en la semana puedes ajustar la meta ideal | L9: VENTA NETA LY (NS)
P10: CAPTURA LOS VALORES ACUMULADOS DEL MES (MTD)
C11: APERTURA-1pm | D11: 1pm - 3pm | E11: 3pm-5pm | F11: 5pm-7pm | G11: 7pm-CIERRE | H11: TOTAL
B12: TRÁFICO POR HORA | H12: =SUM(C12:G12) -> 0 | P12: ATV
B13: PESO DEL TRÁFICO (%) | C13: =+C12/$H$12 -> #DIV/0! | D13: =+D12/$H$12 -> #DIV/0! | E13: =+E12/$H$12 -> #DIV/0! | F13: =+F12/$H$12 -> #DIV/0! | G13: =+G12/$H$12 -> #DIV/0!
B14: META (NS) X HORA | C14: =+C13*$C$5 -> #DIV/0! | D14: =+D13*$C$5 -> #DIV/0! | E14: =+E13*$C$5 -> #DIV/0! | F14: =+F13*$C$5 -> #DIV/0! | G14: =+G13*$C$5 -> #DIV/0! | H14: =+SUM(C14:G14) -> #DIV/0! | P14: AUR
B16: COLABORADORES | D16: HORAS PROGRAMADAS | E16: META DE VENTA | F16: ANALOGOS POR VENDER | G16: WEARABLES POR VENDER | H16: KIDS POR VENDER | I16: CK POR VENDER | L16: Además de cumplir con la meta diaria de la tienda para los No Negociables, cada colaborador debe procurar vender durante su turno al menos: 1 armazón Kids 1 CareKit
B17: ELIAS | D17: 3.5 | E17: =($C$5/$D$25)*D17 -> 0 | F17: =IF((($C$8-$J$5)/$D$25)*D17<1,1,((($C$8-$J$5)/$D$25)*D17)) -> #DIV/0! | H17: =IF(D17>0,MAX(($J$6/$D$25)*D17,1),0) -> #DIV/0! | I17: =IF(D17>0,MAX(($J$7/$D$25)*D17,1),0) -> #DIV/0!
B18: CATALINA | D18: 7 | E18: =($C$5/$D$25)*D18 -> 0 | F18: =IF((($C$8-$J$5)/$D$25)*D18<1,1,((($C$8-$J$5)/$D$25)*D18)) -> #DIV/0! | H18: =IF(D18>0,MAX(($J$6/$D$25)*D18,1),0) -> #DIV/0! | I18: =IF(D18>0,MAX(($J$7/$D$25)*D18,1),0) -> #DIV/0!
B19: VICTOR | D19: 7 | E19: =($C$5/$D$25)*D19 -> 0 | F19: =IF((($C$8-$J$5)/$D$25)*D19<1,1,((($C$8-$J$5)/$D$25)*D19)) -> #DIV/0! | H19: =IF(D19>0,MAX(($J$6/$D$25)*D19,1),0) -> #DIV/0! | I19: =IF(D19>0,MAX(($J$7/$D$25)*D19,1),0) -> #DIV/0!
B20: JIMENA | D20: 7 | E20: =($C$5/$D$25)*D20 -> 0 | F20: =IF((($C$8-$J$5)/$D$25)*D20<1,1,((($C$8-$J$5)/$D$25)*D20)) -> #DIV/0! | H20: =IF(D20>0,MAX(($J$6/$D$25)*D20,1),0) -> #DIV/0! | I20: =IF(D20>0,MAX(($J$7/$D$25)*D20,1),0) -> #DIV/0!
E21: =($C$5/$D$25)*D21 -> 0 | F21: =IF((($C$8-$J$5)/$D$25)*D21<1,1,((($C$8-$J$5)/$D$25)*D21)) -> #DIV/0! | H21: =IF(D21>0,MAX(($J$6/$D$25)*D21,1),0) -> 0 | I21: =IF(D21>0,MAX(($J$7/$D$25)*D21,1),0) -> 0
E22: =($C$5/$D$25)*D22 -> 0 | F22: =IF((($C$8-$J$5)/$D$25)*D22<1,1,((($C$8-$J$5)/$D$25)*D22)) -> #DIV/0! | H22: =IF(D22>0,MAX(($J$6/$D$25)*D22,1),0) -> 0 | I22: =IF(D22>0,MAX(($J$7/$D$25)*D22,1),0) -> 0
E23: =($C$5/$D$25)*D23 -> 0 | F23: =IF((($C$8-$J$5)/$D$25)*D23<1,1,((($C$8-$J$5)/$D$25)*D23)) -> #DIV/0! | H23: =IF(D23>0,MAX(($J$6/$D$25)*D23,1),0) -> 0 | I23: =IF(D23>0,MAX(($J$7/$D$25)*D23,1),0) -> 0
E24: =($C$5/$D$25)*D24 -> 0 | F24: =IF((($C$8-$J$5)/$D$25)*D24<1,1,((($C$8-$J$5)/$D$25)*D24)) -> #DIV/0! | H24: =IF(D24>0,MAX(($J$6/$D$25)*D24,1),0) -> 0 | I24: =IF(D24>0,MAX(($J$7/$D$25)*D24,1),0) -> 0
B25: TOTAL | C25: TOTAL | D25: =+SUM(D17:D24) -> 24.5 | E25: =SUM(E17:E24) -> 0 | F25: =SUM(F17:F24) -> #DIV/0! | G25: =SUM(G17:G24) -> 0 | H25: =+J6 -> #DIV/0! | I25: =+J7 -> #DIV/0!
A27: ¿CÓMO VAMOS?
D29: META | E29: VENTA NETA | F29: META UNIDADES | G29: VENTA UNIDADES | H29: CONVERSION (%) | I29: CRECIMIENTO CONVERSION (%) | J29: WEARABLES % | K29: KIDS% | L29: CAREKITS% | M29: SLP | O29: ONESIGHT
B30: TOTAL DEL DÍA | C30: TOTAL | D30: =+C5 -> 0 | E30: 25600 | F30: =+C8 -> #DIV/0! | G30: 5 | H30: =G41/E41 -> #DIV/0! | I30: =H30-F6 -> #DIV/0! | J30: 0.316 | K30: 0.111 | L30: =P41/G30 -> 0
B32: COLABORADOR | D32: HORAS PROGRAMADAS | E32: INTERACCIONES DURANTE EL DÍA | G32: CLIENTES CONVERTIDOS DURANTE EL DÍA | I32: CONVERSION AL CIERRE | J32: VENTA NETA AL CIERRE | K32: UNIDADES ANALOGAS AL CIERRE | L32: DEMOSTRACIONES WEARABLES AL CIERRE | M32: UNIDADES WEARABLES AL CIERRE | N32: CONVERSION WEREABLE | O32: KIDS AL CIERRE | P32: CAREKITS AL CIERRE | Q32: SLP EOD
B33: =B17 -> ELIAS | D33: =D17 -> 3.5 | I33: =IFERROR(G33/E33,"0") -> 0 | N33: =IFERROR(M33/L33,"0") -> 0
B34: =B18 -> CATALINA | D34: =D18 -> 7 | I34: =IFERROR(G34/E34,"0") -> 0 | N34: =IFERROR(M34/L34,"0") -> 0
B35: =B19 -> VICTOR | D35: =D19 -> 7 | I35: =IFERROR(G35/E35,"0") -> 0 | N35: =IFERROR(M35/L35,"0") -> 0
B36: =B20 -> JIMENA | D36: =D20 -> 7 | I36: =IFERROR(G36/E36,"0") -> 0 | N36: =IFERROR(M36/L36,"0") -> 0
B37: =B21 -> 0 | D37: =D21 -> 0 | I37: =IFERROR(G37/E37,"0") -> 0 | N37: =IFERROR(M37/L37,"0") -> 0
B38: =B22 -> 0 | D38: =D22 -> 0 | I38: =IFERROR(G38/E38,"0") -> 0 | N38: =IFERROR(M38/L38,"0") -> 0
B39: =B23 -> 0 | D39: =D23 -> 0 | I39: =IFERROR(G39/E39,"0") -> 0 | N39: =IFERROR(M39/L39,"0") -> 0
B40: =B24 -> 0 | D40: =D24 -> 0 | I40: =IFERROR(G40/E40,"0") -> 0 | N40: =IFERROR(M40/L40,"0") -> 0
B41: TOTAL | D41: =SUM(D33:D40) -> 24.5 | E41: =SUM(E33:E40) -> 0 | F41: =SUM(F33:F40) -> 0 | G41: =SUM(G33:G40) -> 0 | H41: =SUM(H33:H40) -> 0 | I41: =IFERROR(G41/E41,"0") -> 0 | J41: =SUM(J33:J40) -> 0 | K41: =SUM(K33:K40) -> 0 | L41: =SUM(L33:L40) -> 0 | M41: =SUM(M33:M40) -> 0 | N41: =IFERROR(M41/L41,"0") -> 0 | O41: =SUM(O33:O40) -> 0 | P41: =SUM(P33:P40) -> 0

Sheet PLAN.ACCIÓN_J
B1: ENFOQUE DIARIO! - Nuestro plan de acción | H1: Semana: | J1: Día: | O1: LAS CELDAS EN COLOR VERDE SE LLENAN AUTOMÁTICAMENTE
A2: ¿QÚE ESPERAMOS PARA EL DÍA DE HOY?
B4: HORAS PROGRAMADAS | C4: META (NS) | D4: META PIEZAS | E4: META (NS) PRODUCTIVIDAD | F4: META UNIDADES PRODUCTIVIDAD | I4: ¿Cuál debe ser nuestro ritmo de venta hoy?
B5: =DOMINGO!D25 -> 10 | C5: =DOMINGO!C5 -> 4758 | D5: =DOMINGO!C8 -> 1.0305393 | E5: =DOMINGO!M5 -> 475.8 | F5: =DOMINGO!M6 -> 0.10305393
B7: NUESTROS ESTÁNDARES | I7: NUESTROS NO NEGOCIABLES
B9: LIMPIEZA DE LA TIENDA Barre, limpia y desinfecta. Asegúrate de que la tienda luzca impecable. Pon especial atención al piso de ventas, aparadores, espejos, mobiliario, puerta de acceso, baño y almacén. | I9: RECORDATORIO DE ENTRADA Y SALIDA Al iniciar el día, recuerda al equipo registrar su entrada y, al finalizar su turno, registrar su salida. La precisión de estos registros impacta directamente en los indicadores de productividad.
B10: IMAGEN PERSONAL Somos embajadores de la marca, por lo que nuestra imagen debe reflejar los valores de Sunglass Hut. | I10: SIN USO DE TELÉFONOS CELULARES Evita el uso del teléfono personal durante la jornada laboral. La navegación, publicaciones y mensajes personales deben realizarse fuera del horario de trabajo.
B11: REÚNETE CON EL EQUIPO La junta matutina es clave para tener un gran día. Asegúrate de comunicar: Cómo vamos en la semana y en el mes. La meta del día y las acciones clave para alcanzarla. | I11: MANTENTE FUERA DE LA CAJA Y RESPETA TU ZONA (si aplica) A menos que estés realizando una venta en caja, evita permanecer detrás del mostrador. Si tienes una zona asignada, respétala. Mantén una actitud positiva y utiliza tu energía para atraer clientes a la tienda.
I12: EL SEGUIMIENTO ES FUNDAMENTAL Durante todo el día da seguimiento al desempeño de cada colaborador. El Store Dashboard es la principal herramienta para monitorear resultados, impulsar el desempeño y reaccionar oportunamente cuando las ventas sean lentas.
B14: LOS CINCO SECRETOS / BRANDIES | I14: CUSTOMER JOURNEY
B16: PULIR ES PODER Tu paño de limpieza es una herramienta para generar conexión con el cliente y demostrar el valor del producto. Ofrece limpiar sus lentes al iniciar la conversación para crear una experiencia positiva desde el primer contacto. | I16: EMPIEZA UNA RELACION | L16: GÁNATE SU CONFIANZA | O16: GANA LEALTAD
B17: PÓNTELOS Cuando el cliente se prueba los productos, aumenta su interés y la intención de compra. Utiliza la bandeja de exhibición para ayudarle a comparar opciones e invítalo a probar diferentes modelos hasta encontrar el ideal. | I17: INTERACTÚA Y RELACIONA | L17: DESCUBRE Y APRENDE | O17: VE MÁS ALLÁ
B18: DIVIÉRTETE MÁS La venta no termina con el primer par. Aprovecha la oportunidad para mostrar tres o cuatro opciones adicionales y aumentar las posibilidades de realizar una venta múltiple. | I18: Da la bienvenida genuinamente. | L18: Identifica necesidades (emocional/racional). | O18: Guía la compra con preguntas cerradas.
B19: CUIDALOS Enseñar al cliente cómo cuidar sus lentes mejora su experiencia y fortalece tu papel como asesor especializado. | I19: Observa al cliente y adapta tu acercamiento. | L19: Haz preguntas abiertas, escucha. | O19: Propón formas de pago alternativas.
B20: AJUSTE PERFECTO Un cliente se siente mucho más satisfecho cuando sus lentes quedan perfectamente ajustados. Dedica el tiempo necesario para lograr un ajuste cómodo y personalizado. | I20: Ofrécete a limpiar y ajustar sus gafas. | L20: Recomienda múltiples. | O20: Demuestra que te preocupas, explica cómo cuidar su compra y vuelve a ofrecer Care Kits.
I21: Descubre el próposito de la visita. | L21: Presenta las características como beneficios. | O21: Registra sus datos para el programa de lealtad.
I22: Presenta Wearables, Smart Shopper y las novedades. | L22: Comparte tu experiencia en formas y estilos. Aprovecha promociones y realiza venta adicional (Cross Selling). | O22: Invítalo a compartir su experiencia de compra mediante la encuesta (NPS).
L23: Ofrece Care Kits. | O23: Invítalo a regresar para futuras compras y seguimiento a posibles garantías.
L24: Gestiona las objeciones como oportunidades.
A26: TU ENFOQUE PARA HOY
A29: LOGROS DE HOY Y OPORTUNIDADES PARA MAÑANA

Sheet VIERNES
C1: ENFOQUE DIARIO! - Nuestra meta | H1: Semana: | I1: 31 | J1: Día: | K1: 46241 | L1: Tienda: | M1: VALLEJO | P1: LAS CELDAS EN COLOR VERDE SE LLENAN AUTOMÁTICAMENTE
A2: ¿QÚE ESPERAMOS LOGRAR HOY?
B4: META DEL DÍA | E4: CONVERSIÓN (NO NEGOCIABLE) | H4: OTROS NO NEGOCIABLES | J4: UNIDADES | L4: META DE PRODUCTIVIDAD | P4: CAPTURA LOS VALORES DEL DÍA COMP
B5: META DIARIA | C5: 3620 | E5: TRÁFICO ESPERADO | F5: 16 | H5: WEARABLES | I5: 0.15 | J5: =IF(C7/8100<1,1,C7/8100) -> 1 | L5: VENTA NETA (NS) | M5: =C5/D25 -> 226.25
B6: ANÁLOGOS | C6: =C5*0.85 -> 3077 | E6: META DE CONVERSIÓN (LY+1P.P) | F6: 0.062 | H6: KIDS | I6: 0.05 | J6: =IF(+C8*I6<1,1,C8*I6) -> 1 | L6: UNIDADES | M6: =C8/D25 -> 0.0625 | P6: ATV
B7: WEARABLES | C7: =+C5*0.15 -> 543 | E7: META TRANSACCIONES | F7: =+F5*F6 -> 0.992 | H7: CAREKITS | I7: 0.3 | J7: =IF(C8*I7<1,1,C8*I7) -> 1 | P7: 3620
B8: TOTAL DE UNIDADES | C8: =+C5/P9 -> 1 | E8: META IDEAL (NS)* | F8: =+C5*1.1 -> 3982 | I8: *Si las unidades dan como resultado menor a cero, el objetivo será mínimo una unidad. | L8: COMP LY | P8: AUR
E9: *Si tienes adeudo en la semana puedes ajustar la meta ideal | L9: VENTA NETA LY (NS) | M9: 3620 | P9: 3620
P10: CAPTURA LOS VALORES ACUMULADOS DEL MES (MTD)
C11: APERTURA-1pm | D11: 1pm - 3pm | E11: 3pm-5pm | F11: 5pm-7pm | G11: 7pm-CIERRE | H11: TOTAL
B12: TRÁFICO POR HORA | C12: 3 | D12: 0 | E12: 9 | F12: 3 | G12: 1 | H12: =SUM(C12:G12) -> 16 | P12: ATV
B13: PESO DEL TRÁFICO (%) | C13: =+C12/$H$12 -> 0.1875 | D13: =+D12/$H$12 -> 0 | E13: =+E12/$H$12 -> 0.5625 | F13: =+F12/$H$12 -> 0.1875 | G13: =+G12/$H$12 -> 0.0625 | P13: 7597
B14: META (NS) X HORA | C14: =+C13*$C$5 -> 678.75 | D14: =+D13*$C$5 -> 0 | E14: =+E13*$C$5 -> 2036.25 | F14: =+F13*$C$5 -> 678.75 | G14: =+G13*$C$5 -> 226.25 | H14: =+SUM(C14:G14) -> 3620 | P14: AUR
P15: 3362
B16: COLABORADORES | D16: HORAS PROGRAMADAS | E16: META DE VENTA | F16: ANALOGOS POR VENDER | G16: WEARABLES POR VENDER | H16: KIDS POR VENDER | I16: CK POR VENDER | L16: Además de cumplir con la meta diaria de la tienda para los No Negociables, cada colaborador debe procurar vender durante su turno al menos: 1 armazón Kids 1 CareKit
B17: idalia | D17: 9 | E17: =($C$5/$D$25)*D17 -> 2036.25 | F17: =IF((($C$8-$J$5)/$D$25)*D17<1,1,((($C$8-$J$5)/$D$25)*D17)) -> 1 | H17: =IF(D17>0,MAX(($J$6/$D$25)*D17,1),0) -> 1 | I17: =IF(D17>0,MAX(($J$7/$D$25)*D17,1),0) -> 1
B18: Viviana | D18: 7 | E18: =($C$5/$D$25)*D18 -> 1583.75 | F18: =IF((($C$8-$J$5)/$D$25)*D18<1,1,((($C$8-$J$5)/$D$25)*D18)) -> 1 | H18: =IF(D18>0,MAX(($J$6/$D$25)*D18,1),0) -> 1 | I18: =IF(D18>0,MAX(($J$7/$D$25)*D18,1),0) -> 1
E19: =($C$5/$D$25)*D19 -> 0 | F19: =IF((($C$8-$J$5)/$D$25)*D19<1,1,((($C$8-$J$5)/$D$25)*D19)) -> 1 | H19: =IF(D19>0,MAX(($J$6/$D$25)*D19,1),0) -> 0 | I19: =IF(D19>0,MAX(($J$7/$D$25)*D19,1),0) -> 0
E20: =($C$5/$D$25)*D20 -> 0 | F20: =IF((($C$8-$J$5)/$D$25)*D20<1,1,((($C$8-$J$5)/$D$25)*D20)) -> 1 | H20: =IF(D20>0,MAX(($J$6/$D$25)*D20,1),0) -> 0 | I20: =IF(D20>0,MAX(($J$7/$D$25)*D20,1),0) -> 0
E21: =($C$5/$D$25)*D21 -> 0 | F21: =IF((($C$8-$J$5)/$D$25)*D21<1,1,((($C$8-$J$5)/$D$25)*D21)) -> 1 | H21: =IF(D21>0,MAX(($J$6/$D$25)*D21,1),0) -> 0 | I21: =IF(D21>0,MAX(($J$7/$D$25)*D21,1),0) -> 0
E22: =($C$5/$D$25)*D22 -> 0 | F22: =IF((($C$8-$J$5)/$D$25)*D22<1,1,((($C$8-$J$5)/$D$25)*D22)) -> 1 | H22: =IF(D22>0,MAX(($J$6/$D$25)*D22,1),0) -> 0 | I22: =IF(D22>0,MAX(($J$7/$D$25)*D22,1),0) -> 0
E23: =($C$5/$D$25)*D23 -> 0 | F23: =IF((($C$8-$J$5)/$D$25)*D23<1,1,((($C$8-$J$5)/$D$25)*D23)) -> 1 | H23: =IF(D23>0,MAX(($J$6/$D$25)*D23,1),0) -> 0 | I23: =IF(D23>0,MAX(($J$7/$D$25)*D23,1),0) -> 0
E24: =($C$5/$D$25)*D24 -> 0 | F24: =IF((($C$8-$J$5)/$D$25)*D24<1,1,((($C$8-$J$5)/$D$25)*D24)) -> 1 | H24: =IF(D24>0,MAX(($J$6/$D$25)*D24,1),0) -> 0 | I24: =IF(D24>0,MAX(($J$7/$D$25)*D24,1),0) -> 0
B25: TOTAL | C25: TOTAL | D25: =+SUM(D17:D24) -> 16 | E25: =SUM(E17:E24) -> 3620 | F25: =SUM(F17:F24) -> 8 | G25: =SUM(G17:G24) -> 0 | H25: =+J6 -> 1 | I25: =+J7 -> 1
A27: ¿CÓMO VAMOS?
D29: META | E29: VENTA NETA | F29: META UNIDADES | G29: VENTA UNIDADES | H29: CONVERSION (%) | I29: CRECIMIENTO CONVERSION (%) | J29: WEARABLES % | K29: KIDS% | L29: CAREKITS% | M29: SLP | O29: ONESIGHT
B30: TOTAL DEL DÍA | C30: TOTAL | D30: =+C5 -> 3620 | E30: 25600 | F30: =+C8 -> 1 | G30: 5 | H30: =G41/E41 -> #DIV/0! | I30: =H30-F6 -> #DIV/0! | J30: 0.316 | K30: 0.111 | L30: =P41/G30 -> 0
B32: COLABORADOR | D32: HORAS PROGRAMADAS | E32: INTERACCIONES DURANTE EL DÍA | G32: CLIENTES CONVERTIDOS DURANTE EL DÍA | I32: CONVERSION AL CIERRE | J32: VENTA NETA AL CIERRE | K32: UNIDADES ANALOGAS AL CIERRE | L32: DEMOSTRACIONES WEARABLES AL CIERRE | M32: UNIDADES WEARABLES AL CIERRE | N32: CONVERSION WEREABLE | O32: KIDS AL CIERRE | P32: CAREKITS AL CIERRE | Q32: SLP EOD
B33: =B17 -> idalia | D33: =D17 -> 9 | I33: =IFERROR(G33/E33,"0") -> 0 | N33: =IFERROR(M33/L33,"0") -> 0
B34: =B18 -> Viviana | D34: =D18 -> 7 | I34: =IFERROR(G34/E34,"0") -> 0 | N34: =IFERROR(M34/L34,"0") -> 0
B35: =B19 -> 0 | D35: =D19 -> 0 | I35: =IFERROR(G35/E35,"0") -> 0 | N35: =IFERROR(M35/L35,"0") -> 0
B36: =B20 -> 0 | D36: =D20 -> 0 | I36: =IFERROR(G36/E36,"0") -> 0 | N36: =IFERROR(M36/L36,"0") -> 0
B37: =B21 -> 0 | D37: =D21 -> 0 | I37: =IFERROR(G37/E37,"0") -> 0 | N37: =IFERROR(M37/L37,"0") -> 0
B38: =B22 -> 0 | D38: =D22 -> 0 | I38: =IFERROR(G38/E38,"0") -> 0 | N38: =IFERROR(M38/L38,"0") -> 0
B39: =B23 -> 0 | D39: =D23 -> 0 | I39: =IFERROR(G39/E39,"0") -> 0 | N39: =IFERROR(M39/L39,"0") -> 0
B40: =B24 -> 0 | D40: =D24 -> 0 | I40: =IFERROR(G40/E40,"0") -> 0 | N40: =IFERROR(M40/L40,"0") -> 0
B41: TOTAL | D41: =SUM(D33:D40) -> 16 | E41: =SUM(E33:E40) -> 0 | F41: =SUM(F33:F40) -> 0 | G41: =SUM(G33:G40) -> 0 | H41: =SUM(H33:H40) -> 0 | I41: =IFERROR(G41/E41,"0") -> 0 | J41: =SUM(J33:J40) -> 0 | K41: =SUM(K33:K40) -> 0 | L41: =SUM(L33:L40) -> 0 | M41: =SUM(M33:M40) -> 0 | N41: =IFERROR(M41/L41,"0") -> 0 | O41: =SUM(O33:O40) -> 0 | P41: =SUM(P33:P40) -> 0

Sheet PLAN.ACCIÓN_V
B1: ENFOQUE DIARIO! - Nuestro plan de acción | H1: Semana: | I1: 31 | J1: Día: | K1: 46241 | O1: LAS CELDAS EN COLOR VERDE SE LLENAN AUTOMÁTICAMENTE
A2: ¿QÚE ESPERAMOS PARA EL DÍA DE HOY?
B4: HORAS PROGRAMADAS | C4: META (NS) | D4: META PIEZAS | E4: META (NS) PRODUCTIVIDAD | F4: META UNIDADES PRODUCTIVIDAD | I4: ¿Cuál debe ser nuestro ritmo de venta hoy?
B5: =DOMINGO!D25 -> 10 | C5: =DOMINGO!C5 -> 4758 | D5: =DOMINGO!C8 -> 1.0305393 | E5: =DOMINGO!M5 -> 475.8 | F5: =DOMINGO!M6 -> 0.10305393
B7: NUESTROS ESTÁNDARES | I7: NUESTROS NO NEGOCIABLES
B9: LIMPIEZA DE LA TIENDA Barre, limpia y desinfecta. Asegúrate de que la tienda luzca impecable. Pon especial atención al piso de ventas, aparadores, espejos, mobiliario, puerta de acceso, baño y almacén. | I9: RECORDATORIO DE ENTRADA Y SALIDA Al iniciar el día, recuerda al equipo registrar su entrada y, al finalizar su turno, registrar su salida. La precisión de estos registros impacta directamente en los indicadores de productividad.
B10: IMAGEN PERSONAL Somos embajadores de la marca, por lo que nuestra imagen debe reflejar los valores de Sunglass Hut. | I10: SIN USO DE TELÉFONOS CELULARES Evita el uso del teléfono personal durante la jornada laboral. La navegación, publicaciones y mensajes personales deben realizarse fuera del horario de trabajo.
B11: REÚNETE CON EL EQUIPO La junta matutina es clave para tener un gran día. Asegúrate de comunicar: Cómo vamos en la semana y en el mes. La meta del día y las acciones clave para alcanzarla. | I11: MANTENTE FUERA DE LA CAJA Y RESPETA TU ZONA (si aplica) A menos que estés realizando una venta en caja, evita permanecer detrás del mostrador. Si tienes una zona asignada, respétala. Mantén una actitud positiva y utiliza tu energía para atraer clientes a la tienda.
I12: EL SEGUIMIENTO ES FUNDAMENTAL Durante todo el día da seguimiento al desempeño de cada colaborador. El Store Dashboard es la principal herramienta para monitorear resultados, impulsar el desempeño y reaccionar oportunamente cuando las ventas sean lentas.
B14: LOS CINCO SECRETOS / BRANDIES | I14: CUSTOMER JOURNEY
B16: PULIR ES PODER Tu paño de limpieza es una herramienta para generar conexión con el cliente y demostrar el valor del producto. Ofrece limpiar sus lentes al iniciar la conversación para crear una experiencia positiva desde el primer contacto. | I16: EMPIEZA UNA RELACION | L16: GÁNATE SU CONFIANZA | O16: GANA LEALTAD
