Workbook

Sheet DOMINGO
C1: ENFOQUE DIARIO! - Nuestra meta | H1: Semana: | K1: Día: | M1: Tienda: | O1: LAS CELDAS EN COLOR VERDE SE LLENAN AUTOMÁTICAMENTE
A2: ¿QÚE ESPERAMOS LOGRAR HOY?
B4: META DEL DÍA | G4: CONVERSIÓN (NO NEGOCIABLE) | L4: OTROS NO NEGOCIABLES | O4: UNIDADES
B5: META DIARIA | G5: TRÁFICO ESPERADO | L5: WEARABLES | N5: 0.15 | O5: {=IF(D7/8100<1,1,D7/8100)} -> 1
B6: ANÁLOGOS | D6: {=D5*0.85} -> 0 | G6: META DE CONVERSIÓN (LY+1P.P) | L6: KIDS | N6: 0.05 | O6: {=IF(D8*N6<1,1,D8*N6)}
B7: WEARABLES | D7: {=D5*0.15} -> 0 | G7: META TRANSACCIONES | J7: {=J5*J6} -> 0 | L7: CAREKITS | N7: 0.3 | O7: {=IF(D8*N7<1,1,D8*N7)}
B8: TOTAL DE UNIDADES | D8: {=D5/N14} | G8: META IDEAL (NS)* | J8: {=D5*1.1} -> 0 | L8: *Si las unidades dan como resultado menor a cero, el objetivo será mínimo una unidad.
G9: *Si tienes adeudo en la semana puedes ajustar la meta ideal
L10: VALORES ACUMULADOS DEL MES (MTD) | N10: VALORES DEL DÍA COMP
B11: META DE PRODUCTIVIDAD | G11: COMP LY | L11: ATV | N11: ATV
B12: VENTA NETA (NS) | D12: {=D5/D31} | G12: VENTA NETA LY (NS)
B13: UNIDADES | D13: {=D8/D31} | L13: AUR | N13: AUR
C16: APERTURA-12pm | D16: 1pm - 2pm | E16: 3pm-4pm | F16: 5pm-6pm | G16: 7pm-CIERRE | H16: TOTAL
B17: TRÁFICO POR HORA | H17: {=SUM(C17:G17)} -> 0
B18: PESO DEL TRÁFICO (%) | C18: {=C17/$H$17} | D18: {=D17/$H$17} | E18: {=E17/$H$17} | F18: {=F17/$H$17} | G18: {=G17/$H$17} | H18: {=H17/$H$17}
B19: META (NS) X HORA | C19: {=C18*$D$5} | D19: {=D18*$D$5} | E19: {=E18*$D$5} | F19: {=F18*$D$5} | G19: {=G18*$D$5} | H19: {=SUM(C19:G19)}
B22: COLABORADORES | D22: HORAS PROGRAMADAS | F22: META DE VENTA | G22: ANALOGOS POR VENDER | I22: WEARABLES POR VENDER | K22: KIDS POR VENDER | L22: CK POR VENDER | M22: Además de cumplir con la meta diaria de la tienda para los No Negociables, cada colaborador debe procurar vender durante su turno al menos: 1 armazón Kids 1 CareKit
F23: {=($D$5/$D$31)*D23} | G23: {=(($D$8-$O$5)/$D$31)*D23}
F24: {=($D$5/$D$31)*D24} | G24: {=(($D$8-$O$5)/$D$31)*D24}
F25: {=($D$5/$D$31)*D25} | G25: {=(($D$8-$O$5)/$D$31)*D25}
F26: {=($D$5/$D$31)*D26} | G26: {=(($D$8-$O$5)/$D$31)*D26}
F27: {=($D$5/$D$31)*D27} | G27: {=(($D$8-$O$5)/$D$31)*D27}
F28: {=($D$5/$D$31)*D28} | G28: {=(($D$8-$O$5)/$D$31)*D28}
F29: {=($D$5/$D$31)*D29} | G29: {=(($D$8-$O$5)/$D$31)*D29}
F30: {=($D$5/$D$31)*D30} | G30: {=(($D$8-$O$5)/$D$31)*D30}
B31: TOTAL | D31: {=SUM(D23:D30)} -> 0 | F31: {=SUM(F23:F30)} | G31: {=SUM(G23:H30)} | I31: {=SUM(I23:I30)} -> 0 | K31: {=O6} | L31: {=O7}
A33: ¿CÓMO VAMOS?
B35: TOTAL DEL DÍA | D35: META | E35: VENTA NETA | F35: META UNIDADES | G35: VENTA UNIDADES | H35: CONVERSION (%) | I35: CRECIMIENTO CONVERSION (%) | K35: WEARABLES % | L35: KIDS% | M35: CAREKITS% | N35: SLP | P35: ONESIGHT
D36: {=D5} -> 0 | E36: {=H48} -> 0 | F36: {=D8} | G36: {=I48+K48} -> 0 | H36: {=F48/E48} | I36: {=H36-J6} | K36: {=K48/G36} | L36: {=M48/G36} | M36: {=N48/G36}
B39: COLABORADOR | D39: HORAS PROGRAMADAS | E39: INTERACCIONES DURANTE EL DÍA | F39: CLIENTES CONVERTIDOS DURANTE EL DÍA | G39: CONVERSION AL CIERRE | H39: VENTA NETA AL CIERRE | I39: UNIDADES ANALOGAS AL CIERRE | J39: DEMOSTRACIONES WEARABLES AL CIERRE | K39: UNIDADES WEARABLES AL CIERRE | L39: CONVERSION WEREABLE | M39: KIDS AL CIERRE | N39: CAREKITS AL CIERRE | R39: SLP EOD
B40: {=B23} -> 0 | D40: {=D23} -> 0 | G40: {=_xlfn.IFERROR(F40/E40,"0")} -> 0 | L40: {=_xlfn.IFERROR(K40/J40,"0")} -> 0
B41: {=B24} -> 0 | D41: {=D24} -> 0 | G41: {=_xlfn.IFERROR(F41/E41,"0")} -> 0 | L41: {=_xlfn.IFERROR(K41/J41,"0")} -> 0
B42: {=B25} -> 0 | D42: {=D25} -> 0 | G42: {=_xlfn.IFERROR(F42/E42,"0")} -> 0 | L42: {=_xlfn.IFERROR(K42/J42,"0")} -> 0
B43: {=B26} -> 0 | D43: {=D26} -> 0 | G43: {=_xlfn.IFERROR(F43/E43,"0")} -> 0 | L43: {=_xlfn.IFERROR(K43/J43,"0")} -> 0
B44: {=B27} -> 0 | D44: {=D27} -> 0 | G44: {=_xlfn.IFERROR(F44/E44,"0")} -> 0 | L44: {=_xlfn.IFERROR(K44/J44,"0")} -> 0
B45: {=B28} -> 0 | D45: {=D28} -> 0 | G45: {=_xlfn.IFERROR(F45/E45,"0")} -> 0 | L45: {=_xlfn.IFERROR(K45/J45,"0")} -> 0
B46: {=B29} -> 0 | D46: {=D29} -> 0 | G46: {=_xlfn.IFERROR(F46/E46,"0")} -> 0 | L46: {=_xlfn.IFERROR(K46/J46,"0")} -> 0
B47: {=B30} -> 0 | D47: {=D30} -> 0 | G47: {=_xlfn.IFERROR(F47/E47,"0")} -> 0 | L47: {=_xlfn.IFERROR(K47/J47,"0")} -> 0
B48: TOTAL | D48: {=SUM(D40:D42)} -> 0 | E48: {=SUM(E40:E47)} -> 0 | F48: {=SUM(F40:F47)} -> 0 | G48: {=_xlfn.IFERROR(F48/E48,"0")} -> 0 | H48: {=SUM(H40:H47)} -> 0 | I48: {=SUM(I40:I47)} -> 0 | J48: {=SUM(J40:J47)} -> 0 | K48: {=SUM(K40:K47)} -> 0 | L48: {=_xlfn.IFERROR(K48/J48,"0")} -> 0 | M48: {=SUM(M40:M47)} -> 0 | N48: {=SUM(N40:N47)} -> 0 | Q48: 3

Sheet PLAN ACCION DOMINGO
C1: ENFOQUE DIARIO! - Nuestro plan de acción | I1: Semana: | K1: Día: | N1: LAS CELDAS EN COLOR VERDE SE LLENAN AUTOMÁTICAMENTE
A2: ¿QÚE ESPERAMOS PARA EL DÍA DE HOY?
B4: HORAS PROGRAMADAS | C4: META (NS) | D4: META PIEZAS | E4: META (NS) PRODUCTIVIDAD | F4: META UNIDADES PRODUCTIVIDAD | I4: ¿Cuál debe ser nuestro ritmo de venta hoy?
B5: {='DOMINGO'!D31} -> 0 | C5: {='DOMINGO'!D5} -> 0 | D5: {='DOMINGO'!D8} | E5: {='DOMINGO'!D12} | F5: {='DOMINGO'!D13}
B7: NUESTROS ESTÁNDARES | I7: NUESTROS NO NEGOCIABLES
B9: LIMPIEZA DE LA TIENDA Barre, limpia y desinfecta. Asegúrate de que la tienda luzca impecable. Pon especial atención al piso de ventas, aparadores, espejos, mobiliario, puerta de acceso, baño y almacén. | I9: RECORDATORIO DE ENTRADA Y SALIDA Al iniciar el día, recuerda al equipo registrar su entrada y, al finalizar su turno, registrar su salida. La precisión de estos registros impacta directamente en los indicadores de productividad.
B10: IMAGEN PERSONAL Somos embajadores de la marca, por lo que nuestra imagen debe reflejar los valores de Sunglass Hut. | I10: SIN USO DE TELÉFONOS CELULARES Evita el uso del teléfono personal durante la jornada laboral. La navegación, publicaciones y mensajes personales deben realizarse fuera del horario de trabajo.
B11: REÚNETE CON EL EQUIPO La junta matutina es clave para tener un gran día. Asegúrate de comunicar: Cómo vamos en la semana y en el mes. La meta del día y las acciones clave para alcanzarla. | I11: MANTENTE FUERA DE LA CAJA Y RESPETA TU ZONA (si aplica) A menos que estés realizando una venta en caja, evita permanecer detrás del mostrador. Si tienes una zona asignada, respétala. Mantén una actitud positiva y utiliza tu energía para atraer clientes a la tienda.
I12: EL SEGUIMIENTO ES FUNDAMENTAL Durante todo el día da seguimiento al desempeño de cada colaborador. El Store Dashboard es la principal herramienta para monitorear resultados, impulsar el desempeño y reaccionar oportunamente cuando las ventas sean lentas.
B14: LOS CINCO SECRETOS / BRANDIES | I14: CUSTOMER JOURNEY
B16: PULIR ES PODER Tu paño de limpieza es una herramienta para generar conexión con el cliente y demostrar el valor del producto. Ofrece limpiar sus lentes al iniciar la conversación para crear una experiencia positiva desde el primer contacto. | I16: EMPIEZA UNA RELACION | L16: GÁNATE SU CONFIANZA | O16: GANA LEALTAD
B17: PÓNTELOS Cuando el cliente se prueba los productos, aumenta su interés y la intención de compra. Utiliza la bandeja de exhibición para ayudarle a comparar opciones e invítalo a probar diferentes modelos hasta encontrar el ideal. | I17: INTERACTÚA Y RELACIONA | L17: DESCUBRE Y APRENDE | O17: VE MÁS ALLÁ
B18: DIVIÉRTETE MÁS La venta no termina con el primer par. Aprovecha la oportunidad para mostrar tres o cuatro opciones adicionales y aumentar las posibilidades de realizar una venta múltiple. | I18: Da la bienvenida genuinamente. | L18: Identifica necesidades (emocional/racional). | O18: Guía la compra con preguntas cerradas.
B19: CUIDALOS Enseñar al cliente cómo cuidar sus lentes mejora su experiencia y fortalece tu papel como asesor especializado. | I19: Observa al cliente y adapta tu acercamiento. | L19: Haz preguntas abiertas, escucha. | O19: Propón formas de pago alternativas.
B20: AJUSTE PERFECTO Un cliente se siente mucho más satisfecho cuando sus lentes quedan perfectamente ajustados. Dedica el tiempo necesario para lograr un ajuste cómodo y personalizado. | I20: Ofrécete a limpiar y ajustar sus gafas. | L20: Recomienda múltiples. | O20: Demuestra que te preocupas, explica cómo cuidar su compra y vuelve a ofrecer Care Kits.
I21: Descubre el próposito de la visita. | L21: Presenta las características como beneficios. | O21: Registra sus datos para el programa de lealtad.
I22: Presenta Wearables, Smart Shopper y las novedades. | L22: Comparte tu experiencia en formas y estilos. Aprovecha promociones y realiza venta adicional (Cross Selling). | O22: Invítalo a compartir su experiencia de compra mediante la encuesta (NPS).
L23: Ofrece Care Kits. | O23: Invítalo a regresar para futuras compras y seguimiento a posibles garantías.
L24: Gestiona las objeciones como oportunidades.
A28: TU ENFOQUE PARA HOY
A29: S: ESPECÍFICO
A30: M: MEDIBLE
A31: A: ALCANZABLE
A32: R: RETO
A33: T: TIEMPO
A34: LOGROS DE HOY Y OPORTUNIDADES PARA MAÑANA

Sheet LUNES
C1: ENFOQUE DIARIO! - Nuestra meta | H1: Semana: | K1: Día: | M1: Tienda: | O1: LAS CELDAS EN COLOR VERDE SE LLENAN AUTOMÁTICAMENTE
A2: ¿QÚE ESPERAMOS LOGRAR HOY?
B4: META DEL DÍA | G4: CONVERSIÓN (NO NEGOCIABLE) | L4: OTROS NO NEGOCIABLES | O4: UNIDADES
B5: META DIARIA | G5: TRÁFICO ESPERADO | L5: WEARABLES | N5: 0.15 | O5: {=IF(D7/8100<1,1,D7/8100)} -> 1
B6: ANÁLOGOS | D6: {=D5*0.85} -> 0 | G6: META DE CONVERSIÓN (LY+1P.P) | L6: KIDS | N6: 0.05 | O6: {=IF(D8*N6<1,1,D8*N6)}
B7: WEARABLES | D7: {=D5*0.15} -> 0 | G7: META TRANSACCIONES | J7: {=J5*J6} -> 0 | L7: CAREKITS | N7: 0.3 | O7: {=IF(D8*N7<1,1,D8*N7)}
B8: TOTAL DE UNIDADES | D8: {=D5/N14} | G8: META IDEAL (NS)* | J8: {=D5*1.1} -> 0 | L8: *Si las unidades dan como resultado menor a cero, el objetivo será mínimo una unidad.
G9: *Si tienes adeudo en la semana puedes ajustar la meta ideal
L10: VALORES ACUMULADOS DEL MES (MTD) | N10: VALORES DEL DÍA COMP
B11: META DE PRODUCTIVIDAD | G11: COMP LY | L11: ATV | N11: ATV
B12: VENTA NETA (NS) | D12: {=D5/D31} | G12: VENTA NETA LY (NS)
B13: UNIDADES | D13: {=D8/D31} | L13: AUR | N13: AUR
C16: APERTURA-12pm | D16: 1pm - 2pm | E16: 3pm-4pm | F16: 5pm-6pm | G16: 7pm-CIERRE | H16: TOTAL
B17: TRÁFICO POR HORA | H17: {=SUM(C17:G17)} -> 0
B18: PESO DEL TRÁFICO (%) | C18: {=C17/$H$17} | D18: {=D17/$H$17} | E18: {=E17/$H$17} | F18: {=F17/$H$17} | G18: {=G17/$H$17} | H18: {=H17/$H$17}
B19: META (NS) X HORA | C19: {=C18*$D$5} | D19: {=D18*$D$5} | E19: {=E18*$D$5} | F19: {=F18*$D$5} | G19: {=G18*$D$5} | H19: {=SUM(C19:G19)}
B22: COLABORADORES | D22: HORAS PROGRAMADAS | F22: META DE VENTA | G22: ANALOGOS POR VENDER | I22: WEARABLES POR VENDER | K22: KIDS POR VENDER | L22: CK POR VENDER | M22: Además de cumplir con la meta diaria de la tienda para los No Negociables, cada colaborador debe procurar vender durante su turno al menos: 1 armazón Kids 1 CareKit
B23: {='DOMINGO'!B23} -> 0 | F23: {=($D$5/$D$31)*D23} | G23: {=(($D$8-$O$5)/$D$31)*D23}
B24: {='DOMINGO'!B24} -> 0 | F24: {=($D$5/$D$31)*D24} | G24: {=(($D$8-$O$5)/$D$31)*D24}
B25: {='DOMINGO'!B25} -> 0 | F25: {=($D$5/$D$31)*D25} | G25: {=(($D$8-$O$5)/$D$31)*D25}
B26: {='DOMINGO'!B26} -> 0 | F26: {=($D$5/$D$31)*D26} | G26: {=(($D$8-$O$5)/$D$31)*D26}
B27: {='DOMINGO'!B27} -> 0 | F27: {=($D$5/$D$31)*D27} | G27: {=(($D$8-$O$5)/$D$31)*D27}
B28: {='DOMINGO'!B28} -> 0 | F28: {=($D$5/$D$31)*D28} | G28: {=(($D$8-$O$5)/$D$31)*D28}
B29: {='DOMINGO'!B29} -> 0 | F29: {=($D$5/$D$31)*D29} | G29: {=(($D$8-$O$5)/$D$31)*D29}
B30: {='DOMINGO'!B30} -> 0 | F30: {=($D$5/$D$31)*D30} | G30: {=(($D$8-$O$5)/$D$31)*D30}
B31: TOTAL | D31: {=SUM(D23:D30)} -> 0 | F31: {=SUM(F23:F30)} | G31: {=SUM(G23:H30)} | I31: {=SUM(I23:I30)} -> 0 | K31: {=O6} | L31: {=O7}
A33: ¿CÓMO VAMOS?
B35: TOTAL DEL DÍA | D35: META | E35: VENTA NETA | F35: META UNIDADES | G35: VENTA UNIDADES | H35: CONVERSION (%) | I35: CRECIMIENTO CONVERSION (%) | K35: WEARABLES % | L35: KIDS% | M35: CAREKITS% | N35: SLP | P35: ONESIGHT
D36: {=D5} -> 0 | E36: {=H48} -> 0 | F36: {=D8} | G36: {=I48+K48} -> 0 | H36: {=F48/E48} | I36: {=H36-J6} | K36: {=K48/G36} | L36: {=M48/G36} | M36: {=N48/G36}
B39: COLABORADOR | D39: HORAS PROGRAMADAS | E39: INTERACCIONES DURANTE EL DÍA | F39: CLIENTES CONVERTIDOS DURANTE EL DÍA | G39: CONVERSION AL CIERRE | H39: VENTA NETA AL CIERRE | I39: UNIDADES ANALOGAS AL CIERRE | J39: DEMOSTRACIONES WEARABLES AL CIERRE | K39: UNIDADES WEARABLES AL CIERRE | L39: CONVERSION WEREABLE | M39: KIDS AL CIERRE | N39: CAREKITS AL CIERRE | R39: SLP EOD
B40: {=B23} -> 0 | D40: {=D23} -> 0 | G40: {=_xlfn.IFERROR(F40/E40,"0")} -> 0 | L40: {=_xlfn.IFERROR(K40/J40,"0")} -> 0
B41: {=B24} -> 0 | D41: {=D24} -> 0 | G41: {=_xlfn.IFERROR(F41/E41,"0")} -> 0 | L41: {=_xlfn.IFERROR(K41/J41,"0")} -> 0
B42: {=B25} -> 0 | D42: {=D25} -> 0 | G42: {=_xlfn.IFERROR(F42/E42,"0")} -> 0 | L42: {=_xlfn.IFERROR(K42/J42,"0")} -> 0
B43: {=B26} -> 0 | D43: {=D26} -> 0 | G43: {=_xlfn.IFERROR(F43/E43,"0")} -> 0 | L43: {=_xlfn.IFERROR(K43/J43,"0")} -> 0
B44: {=B27} -> 0 | D44: {=D27} -> 0 | G44: {=_xlfn.IFERROR(F44/E44,"0")} -> 0 | L44: {=_xlfn.IFERROR(K44/J44,"0")} -> 0
B45: {=B28} -> 0 | D45: {=D28} -> 0 | G45: {=_xlfn.IFERROR(F45/E45,"0")} -> 0 | L45: {=_xlfn.IFERROR(K45/J45,"0")} -> 0
B46: {=B29} -> 0 | D46: {=D29} -> 0 | G46: {=_xlfn.IFERROR(F46/E46,"0")} -> 0 | L46: {=_xlfn.IFERROR(K46/J46,"0")} -> 0
B47: {=B30} -> 0 | D47: {=D30} -> 0 | G47: {=_xlfn.IFERROR(F47/E47,"0")} -> 0 | L47: {=_xlfn.IFERROR(K47/J47,"0")} -> 0
B48: TOTAL | D48: {=SUM(D40:D42)} -> 0 | E48: {=SUM(E40:E47)} -> 0 | F48: {=SUM(F40:F47)} -> 0 | G48: {=_xlfn.IFERROR(F48/E48,"0")} -> 0 | H48: {=SUM(H40:H47)} -> 0 | I48: {=SUM(I40:I47)} -> 0 | J48: {=SUM(J40:J47)} -> 0 | K48: {=SUM(K40:K47)} -> 0 | L48: {=_xlfn.IFERROR(K48/J48,"0")} -> 0 | M48: {=SUM(M40:M47)} -> 0 | N48: {=SUM(N40:N47)} -> 0 | Q48: 3

Sheet PLAN ACCION LUNES
C1: ENFOQUE DIARIO! - Nuestro plan de acción | I1: Semana: | K1: Día: | N1: LAS CELDAS EN COLOR VERDE SE LLENAN AUTOMÁTICAMENTE
A2: ¿QÚE ESPERAMOS PARA EL DÍA DE HOY?
B4: HORAS PROGRAMADAS | C4: META (NS) | D4: META PIEZAS | E4: META (NS) PRODUCTIVIDAD | F4: META UNIDADES PRODUCTIVIDAD | I4: ¿Cuál debe ser nuestro ritmo de venta hoy?
B5: {='LUNES'!D31} -> 0 | C5: {='LUNES'!D5} -> 0 | D5: {='LUNES'!D8} | E5: {='LUNES'!D12} | F5: {='LUNES'!D13}
B7: NUESTROS ESTÁNDARES | I7: NUESTROS NO NEGOCIABLES
B9: LIMPIEZA DE LA TIENDA Barre, limpia y desinfecta. Asegúrate de que la tienda luzca impecable. Pon especial atención al piso de ventas, aparadores, espejos, mobiliario, puerta de acceso, baño y almacén. | I9: RECORDATORIO DE ENTRADA Y SALIDA Al iniciar el día, recuerda al equipo registrar su entrada y, al finalizar su turno, registrar su salida. La precisión de estos registros impacta directamente en los indicadores de productividad.
B10: IMAGEN PERSONAL Somos embajadores de la marca, por lo que nuestra imagen debe reflejar los valores de Sunglass Hut. | I10: SIN USO DE TELÉFONOS CELULARES Evita el uso del teléfono personal durante la jornada laboral. La navegación, publicaciones y mensajes personales deben realizarse fuera del horario de trabajo.
B11: REÚNETE CON EL EQUIPO La junta matutina es clave para tener un gran día. Asegúrate de comunicar: Cómo vamos en la semana y en el mes. La meta del día y las acciones clave para alcanzarla. | I11: MANTENTE FUERA DE LA CAJA Y RESPETA TU ZONA (si aplica) A menos que estés realizando una venta en caja, evita permanecer detrás del mostrador. Si tienes una zona asignada, respétala. Mantén una actitud positiva y utiliza tu energía para atraer clientes a la tienda.
I12: EL SEGUIMIENTO ES FUNDAMENTAL Durante todo el día da seguimiento al desempeño de cada colaborador. El Store Dashboard es la principal herramienta para monitorear resultados, impulsar el desempeño y reaccionar oportunamente cuando las ventas sean lentas.
B14: LOS CINCO SECRETOS / BRANDIES | I14: CUSTOMER JOURNEY
B16: PULIR ES PODER Tu paño de limpieza es una herramienta para generar conexión con el cliente y demostrar el valor del producto. Ofrece limpiar sus lentes al iniciar la conversación para crear una experiencia positiva desde el primer contacto. | I16: EMPIEZA UNA RELACION | L16: GÁNATE SU CONFIANZA | O16: GANA LEALTAD
B17: PÓNTELOS Cuando el cliente se prueba los productos, aumenta su interés y la intención de compra. Utiliza la bandeja de exhibición para ayudarle a comparar opciones e invítalo a probar diferentes modelos hasta encontrar el ideal. | I17: INTERACTÚA Y RELACIONA | L17: DESCUBRE Y APRENDE | O17: VE MÁS ALLÁ
B18: DIVIÉRTETE MÁS La venta no termina con el primer par. Aprovecha la oportunidad para mostrar tres o cuatro opciones adicionales y aumentar las posibilidades de realizar una venta múltiple. | I18: Da la bienvenida genuinamente. | L18: Identifica necesidades (emocional/racional). | O18: Guía la compra con preguntas cerradas.
B19: CUIDALOS Enseñar al cliente cómo cuidar sus lentes mejora su experiencia y fortalece tu papel como asesor especializado. | I19: Observa al cliente y adapta tu acercamiento. | L19: Haz preguntas abiertas, escucha. | O19: Propón formas de pago alternativas.
B20: AJUSTE PERFECTO Un cliente se siente mucho más satisfecho cuando sus lentes quedan perfectamente ajustados. Dedica el tiempo necesario para lograr un ajuste cómodo y personalizado. | I20: Ofrécete a limpiar y ajustar sus gafas. | L20: Recomienda múltiples. | O20: Demuestra que te preocupas, explica cómo cuidar su compra y vuelve a ofrecer Care Kits.
I21: Descubre el próposito de la visita. | L21: Presenta las características como beneficios. | O21: Registra sus datos para el programa de lealtad.
I22: Presenta Wearables, Smart Shopper y las novedades. | L22: Comparte tu experiencia en formas y estilos. Aprovecha promociones y realiza venta adicional (Cross Selling). | O22: Invítalo a compartir su experiencia de compra mediante la encuesta (NPS).
L23: Ofrece Care Kits. | O23: Invítalo a regresar para futuras compras y seguimiento a posibles garantías.
L24: Gestiona las objeciones como oportunidades.
A28: TU ENFOQUE PARA HOY
A29: S: ESPECÍFICO
A30: M: MEDIBLE
A31: A: ALCANZABLE
A32: R: RETO
A33: T: TIEMPO
A34: LOGROS DE HOY Y OPORTUNIDADES PARA MAÑANA

Sheet MARTES
C1: ENFOQUE DIARIO! - Nuestra meta | H1: Semana: | K1: Día: | M1: Tienda: | O1: LAS CELDAS EN COLOR VERDE SE LLENAN AUTOMÁTICAMENTE
A2: ¿QÚE ESPERAMOS LOGRAR HOY?
B4: META DEL DÍA | G4: CONVERSIÓN (NO NEGOCIABLE) | L4: OTROS NO NEGOCIABLES | O4: UNIDADES
B5: META DIARIA | G5: TRÁFICO ESPERADO | L5: WEARABLES | N5: 0.15 | O5: {=IF(D7/8100<1,1,D7/8100)} -> 1
B6: ANÁLOGOS | D6: {=D5*0.85} -> 0 | G6: META DE CONVERSIÓN (LY+1P.P) | L6: KIDS | N6: 0.05 | O6: {=IF(D8*N6<1,1,D8*N6)}
B7: WEARABLES | D7: {=D5*0.15} -> 0 | G7: META TRANSACCIONES | J7: {=J5*J6} -> 0 | L7: CAREKITS | N7: 0.3 | O7: {=IF(D8*N7<1,1,D8*N7)}
B8: TOTAL DE UNIDADES | D8: {=D5/N14} | G8: META IDEAL (NS)* | J8: {=D5*1.1} -> 0 | L8: *Si las unidades dan como resultado menor a cero, el objetivo será mínimo una unidad.
G9: *Si tienes adeudo en la semana puedes ajustar la meta ideal
L10: VALORES ACUMULADOS DEL MES (MTD) | N10: VALORES DEL DÍA COMP
B11: META DE PRODUCTIVIDAD | G11: COMP LY | L11: ATV | N11: ATV
B12: VENTA NETA (NS) | D12: {=D5/D31} | G12: VENTA NETA LY (NS)
B13: UNIDADES | D13: {=D8/D31} | L13: AUR | N13: AUR
C16: APERTURA-12pm | D16: 1pm - 2pm | E16: 3pm-4pm | F16: 5pm-6pm | G16: 7pm-CIERRE | H16: TOTAL
B17: TRÁFICO POR HORA | H17: {=SUM(C17:G17)} -> 0
B18: PESO DEL TRÁFICO (%) | C18: {=C17/$H$17} | D18: {=D17/$H$17} | E18: {=E17/$H$17} | F18: {=F17/$H$17} | G18: {=G17/$H$17} | H18: {=H17/$H$17}
B19: META (NS) X HORA | C19: {=C18*$D$5} | D19: {=D18*$D$5} | E19: {=E18*$D$5} | F19: {=F18*$D$5} | G19: {=G18*$D$5} | H19: {=SUM(C19:G19)}
B22: COLABORADORES | D22: HORAS PROGRAMADAS | F22: META DE VENTA | G22: ANALOGOS POR VENDER | I22: WEARABLES POR VENDER | K22: KIDS POR VENDER | L22: CK POR VENDER | M22: Además de cumplir con la meta diaria de la tienda para los No Negociables, cada colaborador debe procurar vender durante su turno al menos: 1 armazón Kids 1 CareKit
B23: {='DOMINGO'!B23} -> 0 | F23: {=($D$5/$D$31)*D23} | G23: {=(($D$8-$O$5)/$D$31)*D23}
B24: {='DOMINGO'!B24} -> 0 | F24: {=($D$5/$D$31)*D24} | G24: {=(($D$8-$O$5)/$D$31)*D24}
B25: {='DOMINGO'!B25} -> 0 | F25: {=($D$5/$D$31)*D25} | G25: {=(($D$8-$O$5)/$D$31)*D25}
B26: {='DOMINGO'!B26} -> 0 | F26: {=($D$5/$D$31)*D26} | G26: {=(($D$8-$O$5)/$D$31)*D26}
B27: {='DOMINGO'!B27} -> 0 | F27: {=($D$5/$D$31)*D27} | G27: {=(($D$8-$O$5)/$D$31)*D27}
B28: {='DOMINGO'!B28} -> 0 | F28: {=($D$5/$D$31)*D28} | G28: {=(($D$8-$O$5)/$D$31)*D28}
B29: {='DOMINGO'!B29} -> 0 | F29: {=($D$5/$D$31)*D29} | G29: {=(($D$8-$O$5)/$D$31)*D29}
B30: {='DOMINGO'!B30} -> 0 | F30: {=($D$5/$D$31)*D30} | G30: {=(($D$8-$O$5)/$D$31)*D30}
B31: TOTAL | D31: {=SUM(D23:D30)} -> 0 | F31: {=SUM(F23:F30)} | G31: {=SUM(G23:H30)} | I31: {=SUM(I23:I30)} -> 0 | K31: {=O6} | L31: {=O7}
A33: ¿CÓMO VAMOS?
B35: TOTAL DEL DÍA | D35: META | E35: VENTA NETA | F35: META UNIDADES | G35: VENTA UNIDADES | H35: CONVERSION (%) | I35: CRECIMIENTO CONVERSION (%) | K35: WEARABLES % | L35: KIDS% | M35: CAREKITS% | N35: SLP | P35: ONESIGHT
D36: {=D5} -> 0 | E36: {=H48} -> 0 | F36: {=D8} | G36: {=I48+K48} -> 0 | H36: {=F48/E48} | I36: {=H36-J6} | K36: {=K48/G36} | L36: {=M48/G36} | M36: {=N48/G36}
B39: COLABORADOR | D39: HORAS PROGRAMADAS | E39: INTERACCIONES DURANTE EL DÍA | F39: CLIENTES CONVERTIDOS DURANTE EL DÍA | G39: CONVERSION AL CIERRE | H39: VENTA NETA AL CIERRE | I39: UNIDADES ANALOGAS AL CIERRE | J39: DEMOSTRACIONES WEARABLES AL CIERRE | K39: UNIDADES WEARABLES AL CIERRE | L39: CONVERSION WEREABLE | M39: KIDS AL CIERRE | N39: CAREKITS AL CIERRE | R39: SLP EOD
B40: {=B23} -> 0 | D40: {=D23} -> 0 | G40: {=_xlfn.IFERROR(F40/E40,"0")} -> 0 | L40: {=_xlfn.IFERROR(K40/J40,"0")} -> 0
B41: {=B24} -> 0 | D41: {=D24} -> 0 | G41: {=_xlfn.IFERROR(F41/E41,"0")} -> 0 | L41: {=_xlfn.IFERROR(K41/J41,"0")} -> 0
B42: {=B25} -> 0 | D42: {=D25} -> 0 | G42: {=_xlfn.IFERROR(F42/E42,"0")} -> 0 | L42: {=_xlfn.IFERROR(K42/J42,"0")} -> 0
B43: {=B26} -> 0 | D43: {=D26} -> 0 | G43: {=_xlfn.IFERROR(F43/E43,"0")} -> 0 | L43: {=_xlfn.IFERROR(K43/J43,"0")} -> 0
B44: {=B27} -> 0 | D44: {=D27} -> 0 | G44: {=_xlfn.IFERROR(F44/E44,"0")} -> 0 | L44: {=_xlfn.IFERROR(K44/J44,"0")} -> 0
B45: {=B28} -> 0 | D45: {=D28} -> 0 | G45: {=_xlfn.IFERROR(F45/E45,"0")} -> 0 | L45: {=_xlfn.IFERROR(K45/J45,"0")} -> 0
B46: {=B29} -> 0 | D46: {=D29} -> 0 | G46: {=_xlfn.IFERROR(F46/E46,"0")} -> 0 | L46: {=_xlfn.IFERROR(K46/J46,"0")} -> 0
B47: {=B30} -> 0 | D47: {=D30} -> 0 | G47: {=_xlfn.IFERROR(F47/E47,"0")} -> 0 | L47: {=_xlfn.IFERROR(K47/J47,"0")} -> 0
B48: TOTAL | D48: {=SUM(D40:D42)} -> 0 | E48: {=SUM(E40:E47)} -> 0 | F48: {=SUM(F40:F47)} -> 0 | G48: {=_xlfn.IFERROR(F48/E48,"0")} -> 0 | H48: {=SUM(H40:H47)} -> 0 | I48: {=SUM(I40:I47)} -> 0 | J48: {=SUM(J40:J47)} -> 0 | K48: {=SUM(K40:K47)} -> 0 | L48: {=_xlfn.IFERROR(K48/J48,"0")} -> 0 | M48: {=SUM(M40:M47)} -> 0 | N48: {=SUM(N40:N47)} -> 0 | Q48: 3

Sheet PLAN ACCION MARTES 
C1: ENFOQUE DIARIO! - Nuestro plan de acción | I1: Semana: | K1: Día: | N1: LAS CELDAS EN COLOR VERDE SE LLENAN AUTOMÁTICAMENTE
A2: ¿QÚE ESPERAMOS PARA EL DÍA DE HOY?
B4: HORAS PROGRAMADAS | C4: META (NS) | D4: META PIEZAS | E4: META (NS) PRODUCTIVIDAD | F4: META UNIDADES PRODUCTIVIDAD | I4: ¿Cuál debe ser nuestro ritmo de venta hoy?
B5: {='MARTES'!D31} -> 0 | C5: {='MARTES'!D5} -> 0 | D5: {='MARTES'!D8} | E5: {='MARTES'!D12} | F5: {='MARTES'!D13}
B7: NUESTROS ESTÁNDARES | I7: NUESTROS NO NEGOCIABLES
B9: LIMPIEZA DE LA TIENDA Barre, limpia y desinfecta. Asegúrate de que la tienda luzca impecable. Pon especial atención al piso de ventas, aparadores, espejos, mobiliario, puerta de acceso, baño y almacén. | I9: RECORDATORIO DE ENTRADA Y SALIDA Al iniciar el día, recuerda al equipo registrar su entrada y, al finalizar su turno, registrar su salida. La precisión de estos registros impacta directamente en los indicadores de productividad.
B10: IMAGEN PERSONAL Somos embajadores de la marca, por lo que nuestra imagen debe reflejar los valores de Sunglass Hut. | I10: SIN USO DE TELÉFONOS CELULARES Evita el uso del teléfono personal durante la jornada laboral. La navegación, publicaciones y mensajes personales deben realizarse fuera del horario de trabajo.
B11: REÚNETE CON EL EQUIPO La junta matutina es clave para tener un gran día. Asegúrate de comunicar: Cómo vamos en la semana y en el mes. La meta del día y las acciones clave para alcanzarla. | I11: MANTENTE FUERA DE LA CAJA Y RESPETA TU ZONA (si aplica) A menos que estés realizando una venta en caja, evita permanecer detrás del mostrador. Si tienes una zona asignada, respétala. Mantén una actitud positiva y utiliza tu energía para atraer clientes a la tienda.
I12: EL SEGUIMIENTO ES FUNDAMENTAL Durante todo el día da seguimiento al desempeño de cada colaborador. El Store Dashboard es la principal herramienta para monitorear resultados, impulsar el desempeño y reaccionar oportunamente cuando las ventas sean lentas.
B14: LOS CINCO SECRETOS / BRANDIES | I14: CUSTOMER JOURNEY
B16: PULIR ES PODER Tu paño de limpieza es una herramienta para generar conexión con el cliente y demostrar el valor del producto. Ofrece limpiar sus lentes al iniciar la conversación para crear una experiencia positiva desde el primer contacto. | I16: EMPIEZA UNA RELACION | L16: GÁNATE SU CONFIANZA | O16: GANA LEALTAD
B17: PÓNTELOS Cuando el cliente se prueba los productos, aumenta su interés y la intención de compra. Utiliza la bandeja de exhibición para ayudarle a comparar opciones e invítalo a probar diferentes modelos hasta encontrar el ideal. | I17: INTERACTÚA Y RELACIONA | L17: DESCUBRE Y APRENDE | O17: VE MÁS ALLÁ
B18: DIVIÉRTETE MÁS La venta no termina con el primer par. Aprovecha la oportunidad para mostrar tres o cuatro opciones adicionales y aumentar las posibilidades de realizar una venta múltiple. | I18: Da la bienvenida genuinamente. | L18: Identifica necesidades (emocional/racional). | O18: Guía la compra con preguntas cerradas.
B19: CUIDALOS Enseñar al cliente cómo cuidar sus lentes mejora su experiencia y fortalece tu papel como asesor especializado. | I19: Observa al cliente y adapta tu acercamiento. | L19: Haz preguntas abiertas, escucha. | O19: Propón formas de pago alternativas.
B20: AJUSTE PERFECTO Un cliente se siente mucho más satisfecho cuando sus lentes quedan perfectamente ajustados. Dedica el tiempo necesario para lograr un ajuste cómodo y personalizado. | I20: Ofrécete a limpiar y ajustar sus gafas. | L20: Recomienda múltiples. | O20: Demuestra que te preocupas, explica cómo cuidar su compra y vuelve a ofrecer Care Kits.
I21: Descubre el próposito de la visita. | L21: Presenta las características como beneficios. | O21: Registra sus datos para el programa de lealtad.
I22: Presenta Wearables, Smart Shopper y las novedades. | L22: Comparte tu experiencia en formas y estilos. Aprovecha promociones y realiza venta adicional (Cross Selling). | O22: Invítalo a compartir su experiencia de compra mediante la encuesta (NPS).
L23: Ofrece Care Kits. | O23: Invítalo a regresar para futuras compras y seguimiento a posibles garantías.
L24: Gestiona las objeciones como oportunidades.
A28: TU ENFOQUE PARA HOY
A29: S: ESPECÍFICO
A30: M: MEDIBLE
A31: A: ALCANZABLE
A32: R: RETO
A33: T: TIEMPO
A34: LOGROS DE HOY Y OPORTUNIDADES PARA MAÑANA

Sheet MIÉRCOLES
C1: ENFOQUE DIARIO! - Nuestra meta | H1: Semana: | K1: Día: | M1: Tienda: | O1: LAS CELDAS EN COLOR VERDE SE LLENAN AUTOMÁTICAMENTE
A2: ¿QÚE ESPERAMOS LOGRAR HOY?
B4: META DEL DÍA | G4: CONVERSIÓN (NO NEGOCIABLE) | L4: OTROS NO NEGOCIABLES | O4: UNIDADES
B5: META DIARIA | G5: TRÁFICO ESPERADO | L5: WEARABLES | N5: 0.15 | O5: {=IF(D7/8100<1,1,D7/8100)} -> 1
B6: ANÁLOGOS | D6: {=D5*0.85} -> 0 | G6: META DE CONVERSIÓN (LY+1P.P) | L6: KIDS | N6: 0.05 | O6: {=IF(D8*N6<1,1,D8*N6)}
B7: WEARABLES | D7: {=D5*0.15} -> 0 | G7: META TRANSACCIONES | J7: {=J5*J6} -> 0 | L7: CAREKITS | N7: 0.3 | O7: {=IF(D8*N7<1,1,D8*N7)}
B8: TOTAL DE UNIDADES | D8: {=D5/N14} | G8: META IDEAL (NS)* | J8: {=D5*1.1} -> 0 | L8: *Si las unidades dan como resultado menor a cero, el objetivo será mínimo una unidad.
G9: *Si tienes adeudo en la semana puedes ajustar la meta ideal
L10: VALORES ACUMULADOS DEL MES (MTD) | N10: VALORES DEL DÍA COMP
B11: META DE PRODUCTIVIDAD | G11: COMP LY | L11: ATV | N11: ATV
B12: VENTA NETA (NS) | D12: {=D5/D31} | G12: VENTA NETA LY (NS)
B13: UNIDADES | D13: {=D8/D31} | L13: AUR | N13: AUR
C16: APERTURA-12pm | D16: 1pm - 2pm | E16: 3pm-4pm | F16: 5pm-6pm | G16: 7pm-CIERRE | H16: TOTAL
B17: TRÁFICO POR HORA | H17: {=SUM(C17:G17)} -> 0
B18: PESO DEL TRÁFICO (%) | C18: {=C17/$H$17} | D18: {=D17/$H$17} | E18: {=E17/$H$17} | F18: {=F17/$H$17} | G18: {=G17/$H$17} | H18: {=H17/$H$17}
B19: META (NS) X HORA | C19: {=C18*$D$5} | D19: {=D18*$D$5} | E19: {=E18*$D$5} | F19: {=F18*$D$5} | G19: {=G18*$D$5} | H19: {=SUM(C19:G19)}
B22: COLABORADORES | D22: HORAS PROGRAMADAS | F22: META DE VENTA | G22: ANALOGOS POR VENDER | I22: WEARABLES POR VENDER | K22: KIDS POR VENDER | L22: CK POR VENDER | M22: Además de cumplir con la meta diaria de la tienda para los No Negociables, cada colaborador debe procurar vender durante su turno al menos: 1 armazón Kids 1 CareKit
B23: {='DOMINGO'!B23} -> 0 | F23: {=($D$5/$D$31)*D23} | G23: {=(($D$8-$O$5)/$D$31)*D23}
B24: {='DOMINGO'!B24} -> 0 | F24: {=($D$5/$D$31)*D24} | G24: {=(($D$8-$O$5)/$D$31)*D24}
B25: {='DOMINGO'!B25} -> 0 | F25: {=($D$5/$D$31)*D25} | G25: {=(($D$8-$O$5)/$D$31)*D25}
B26: {='DOMINGO'!B26} -> 0 | F26: {=($D$5/$D$31)*D26} | G26: {=(($D$8-$O$5)/$D$31)*D26}
B27: {='DOMINGO'!B27} -> 0 | F27: {=($D$5/$D$31)*D27} | G27: {=(($D$8-$O$5)/$D$31)*D27}
B28: {='DOMINGO'!B28} -> 0 | F28: {=($D$5/$D$31)*D28} | G28: {=(($D$8-$O$5)/$D$31)*D28}
B29: {='DOMINGO'!B29} -> 0 | F29: {=($D$5/$D$31)*D29} | G29: {=(($D$8-$O$5)/$D$31)*D29}
B30: {='DOMINGO'!B30} -> 0 | F30: {=($D$5/$D$31)*D30} | G30: {=(($D$8-$O$5)/$D$31)*D30}
B31: TOTAL | D31: {=SUM(D23:D30)} -> 0 | F31: {=SUM(F23:F30)} | G31: {=SUM(G23:H30)} | I31: {=SUM(I23:I30)} -> 0 | K31: {=O6} | L31: {=O7}
A33: ¿CÓMO VAMOS?
B35: TOTAL DEL DÍA | D35: META | E35: VENTA NETA | F35: META UNIDADES | G35: VENTA UNIDADES | H35: CONVERSION (%) | I35: CRECIMIENTO CONVERSION (%) | K35: WEARABLES % | L35: KIDS% | M35: CAREKITS% | N35: SLP | P35: ONESIGHT
D36: {=D5} -> 0 | E36: {=H48} -> 0 | F36: {=D8} | G36: {=I48+K48} -> 0 | H36: {=F48/E48} | I36: {=H36-J6} | K36: {=K48/G36} | L36: {=M48/G36} | M36: {=N48/G36}
B39: COLABORADOR | D39: HORAS PROGRAMADAS | E39: INTERACCIONES DURANTE EL DÍA | F39: CLIENTES CONVERTIDOS DURANTE EL DÍA | G39: CONVERSION AL CIERRE | H39: VENTA NETA AL CIERRE | I39: UNIDADES ANALOGAS AL CIERRE | J39: DEMOSTRACIONES WEARABLES AL CIERRE | K39: UNIDADES WEARABLES AL CIERRE | L39: CONVERSION WEREABLE | M39: KIDS AL CIERRE | N39: CAREKITS AL CIERRE | R39: SLP EOD
B40: {=B23} -> 0 | D40: {=D23} -> 0 | G40: {=_xlfn.IFERROR(F40/E40,"0")} -> 0 | L40: {=_xlfn.IFERROR(K40/J40,"0")} -> 0
B41: {=B24} -> 0 | D41: {=D24} -> 0 | G41: {=_xlfn.IFERROR(F41/E41,"0")} -> 0 | L41: {=_xlfn.IFERROR(K41/J41,"0")} -> 0
B42: {=B25} -> 0 | D42: {=D25} -> 0 | G42: {=_xlfn.IFERROR(F42/E42,"0")} -> 0 | L42: {=_xlfn.IFERROR(K42/J42,"0")} -> 0
B43: {=B26} -> 0 | D43: {=D26} -> 0 | G43: {=_xlfn.IFERROR(F43/E43,"0")} -> 0 | L43: {=_xlfn.IFERROR(K43/J43,"0")} -> 0
B44: {=B27} -> 0 | D44: {=D27} -> 0 | G44: {=_xlfn.IFERROR(F44/E44,"0")} -> 0 | L44: {=_xlfn.IFERROR(K44/J44,"0")} -> 0
B45: {=B28} -> 0 | D45: {=D28} -> 0 | G45: {=_xlfn.IFERROR(F45/E45,"0")} -> 0 | L45: {=_xlfn.IFERROR(K45/J45,"0")} -> 0
B46: {=B29} -> 0 | D46: {=D29} -> 0 | G46: {=_xlfn.IFERROR(F46/E46,"0")} -> 0 | L46: {=_xlfn.IFERROR(K46/J46,"0")} -> 0
B47: {=B30} -> 0 | D47: {=D30} -> 0 | G47: {=_xlfn.IFERROR(F47/E47,"0")} -> 0 | L47: {=_xlfn.IFERROR(K47/J47,"0")} -> 0
B48: TOTAL | D48: {=SUM(D40:D42)} -> 0 | E48: {=SUM(E40:E47)} -> 0 | F48: {=SUM(F40:F47)} -> 0 | G48: {=_xlfn.IFERROR(F48/E48,"0")} -> 0 | H48: {=SUM(H40:H47)} -> 0 | I48: {=SUM(I40:I47)} -> 0 | J48: {=SUM(J40:J47)} -> 0 | K48: {=SUM(K40:K47)} -> 0 | L48: {=_xlfn.IFERROR(K48/J48,"0")} -> 0 | M48: {=SUM(M40:M47)} -> 0 | N48: {=SUM(N40:N47)} -> 0 | Q48: 3

Sheet PLAN ACCION MIÉRCOLES
C1: ENFOQUE DIARIO! - Nuestro plan de acción | I1: Semana: | K1: Día: | N1: LAS CELDAS EN COLOR VERDE SE LLENAN AUTOMÁTICAMENTE
A2: ¿QÚE ESPERAMOS PARA EL DÍA DE HOY?
B4: HORAS PROGRAMADAS | C4: META (NS) | D4: META PIEZAS | E4: META (NS) PRODUCTIVIDAD | F4: META UNIDADES PRODUCTIVIDAD | I4: ¿Cuál debe ser nuestro ritmo de venta hoy?
B5: {='MIÉRCOLES'!D31} -> 0 | C5: {='MIÉRCOLES'!D5} -> 0 | D5: {='MIÉRCOLES'!D8} | E5: {='MIÉRCOLES'!D12} | F5: {='MIÉRCOLES'!D13}
B7: NUESTROS ESTÁNDARES | I7: NUESTROS NO NEGOCIABLES
B9: LIMPIEZA DE LA TIENDA Barre, limpia y desinfecta. Asegúrate de que la tienda luzca impecable. Pon especial atención al piso de ventas, aparadores, espejos, mobiliario, puerta de acceso, baño y almacén. | I9: RECORDATORIO DE ENTRADA Y SALIDA Al iniciar el día, recuerda al equipo registrar su entrada y, al finalizar su turno, registrar su salida. La precisión de estos registros impacta directamente en los indicadores de productividad.
B10: IMAGEN PERSONAL Somos embajadores de la marca, por lo que nuestra imagen debe reflejar los valores de Sunglass Hut. | I10: SIN USO DE TELÉFONOS CELULARES Evita el uso del teléfono personal durante la jornada laboral. La navegación, publicaciones y mensajes personales deben realizarse fuera del horario de trabajo.
B11: REÚNETE CON EL EQUIPO La junta matutina es clave para tener un gran día. Asegúrate de comunicar: Cómo vamos en la semana y en el mes. La meta del día y las acciones clave para alcanzarla. | I11: MANTENTE FUERA DE LA CAJA Y RESPETA TU ZONA (si aplica) A menos que estés realizando una venta en caja, evita permanecer detrás del mostrador. Si tienes una zona asignada, respétala. Mantén una actitud positiva y utiliza tu energía para atraer clientes a la tienda.
I12: EL SEGUIMIENTO ES FUNDAMENTAL Durante todo el día da seguimiento al desempeño de cada colaborador. El Store Dashboard es la principal herramienta para monitorear resultados, impulsar el desempeño y reaccionar oportunamente cuando las ventas sean lentas.
B14: LOS CINCO SECRETOS / BRANDIES | I14: CUSTOMER JOURNEY
B16: PULIR ES PODER Tu paño de limpieza es una herramienta para generar conexión con el cliente y demostrar el valor del producto. Ofrece limpiar sus lentes al iniciar la conversación para crear una experiencia positiva desde el primer contacto. | I16: EMPIEZA UNA RELACION | L16: GÁNATE SU CONFIANZA | O16: GANA LEALTAD
B17: PÓNTELOS Cuando el cliente se prueba los productos, aumenta su interés y la intención de compra. Utiliza la bandeja de exhibición para ayudarle a comparar opciones e invítalo a probar diferentes modelos hasta encontrar el ideal. | I17: INTERACTÚA Y RELACIONA | L17: DESCUBRE Y APRENDE | O17: VE MÁS ALLÁ
B18: DIVIÉRTETE MÁS La venta no termina con el primer par. Aprovecha la oportunidad para mostrar tres o cuatro opciones adicionales y aumentar las posibilidades de realizar una venta múltiple. | I18: Da la bienvenida genuinamente. | L18: Identifica necesidades (emocional/racional). | O18: Guía la compra con preguntas cerradas.
B19: CUIDALOS Enseñar al cliente cómo cuidar sus lentes mejora su experiencia y fortalece tu papel como asesor especializado. | I19: Observa al cliente y adapta tu acercamiento. | L19: Haz preguntas abiertas, escucha. | O19: Propón formas de pago alternativas.
B20: AJUSTE PERFECTO Un cliente se siente mucho más satisfecho cuando sus lentes quedan perfectamente ajustados. Dedica el tiempo necesario para lograr un ajuste cómodo y personalizado. | I20: Ofrécete a limpiar y ajustar sus gafas. | L20: Recomienda múltiples. | O20: Demuestra que te preocupas, explica cómo cuidar su compra y vuelve a ofrecer Care Kits.
I21: Descubre el próposito de la visita. | L21: Presenta las características como beneficios. | O21: Registra sus datos para el programa de lealtad.
I22: Presenta Wearables, Smart Shopper y las novedades. | L22: Comparte tu experiencia en formas y estilos. Aprovecha promociones y realiza venta adicional (Cross Selling). | O22: Invítalo a compartir su experiencia de compra mediante la encuesta (NPS).
L23: Ofrece Care Kits. | O23: Invítalo a regresar para futuras compras y seguimiento a posibles garantías.
L24: Gestiona las objeciones como oportunidades.
A28: TU ENFOQUE PARA HOY
A29: S: ESPECÍFICO
A30: M: MEDIBLE
A31: A: ALCANZABLE
A32: R: RETO
A33: T: TIEMPO
A34: LOGROS DE HOY Y OPORTUNIDADES PARA MAÑANA

Sheet JUEVES
C1: ENFOQUE DIARIO! - Nuestra meta | H1: Semana: | K1: Día: | M1: Tienda: | O1: LAS CELDAS EN COLOR VERDE SE LLENAN AUTOMÁTICAMENTE
A2: ¿QÚE ESPERAMOS LOGRAR HOY?
B4: META DEL DÍA | G4: CONVERSIÓN (NO NEGOCIABLE) | L4: OTROS NO NEGOCIABLES | O4: UNIDADES
B5: META DIARIA | G5: TRÁFICO ESPERADO | L5: WEARABLES | N5: 0.15 | O5: {=IF(D7/8100<1,1,D7/8100)} -> 1
B6: ANÁLOGOS | D6: {=D5*0.85} -> 0 | G6: META DE CONVERSIÓN (LY+1P.P) | L6: KIDS | N6: 0.05 | O6: {=IF(D8*N6<1,1,D8*N6)}
B7: WEARABLES | D7: {=D5*0.15} -> 0 | G7: META TRANSACCIONES | J7: {=J5*J6} -> 0 | L7: CAREKITS | N7: 0.3 | O7: {=IF(D8*N7<1,1,D8*N7)}
B8: TOTAL DE UNIDADES | D8: {=D5/N14} | G8: META IDEAL (NS)* | J8: {=D5*1.1} -> 0 | L8: *Si las unidades dan como resultado menor a cero, el objetivo será mínimo una unidad.
G9: *Si tienes adeudo en la semana puedes ajustar la meta ideal
L10: VALORES ACUMULADOS DEL MES (MTD) | N10: VALORES DEL DÍA COMP
B11: META DE PRODUCTIVIDAD | G11: COMP LY | L11: ATV | N11: ATV
B12: VENTA NETA (NS) | D12: {=D5/D31} | G12: VENTA NETA LY (NS)
B13: UNIDADES | D13: {=D8/D31} | L13: AUR | N13: AUR
C16: APERTURA-12pm | D16: 1pm - 2pm | E16: 3pm-4pm | F16: 5pm-6pm | G16: 7pm-CIERRE | H16: TOTAL
B17: TRÁFICO POR HORA | H17: {=SUM(C17:G17)} -> 0
B18: PESO DEL TRÁFICO (%) | C18: {=C17/$H$17} | D18: {=D17/$H$17} | E18: {=E17/$H$17} | F18: {=F17/$H$17} | G18: {=G17/$H$17} | H18: {=H17/$H$17}
B19: META (NS) X HORA | C19: {=C18*$D$5} | D19: {=D18*$D$5} | E19: {=E18*$D$5} | F19: {=F18*$D$5} | G19: {=G18*$D$5} | H19: {=SUM(C19:G19)}
B22: COLABORADORES | D22: HORAS PROGRAMADAS | F22: META DE VENTA | G22: ANALOGOS POR VENDER | I22: WEARABLES POR VENDER | K22: KIDS POR VENDER | L22: CK POR VENDER | M22: Además de cumplir con la meta diaria de la tienda para los No Negociables, cada colaborador debe procurar vender durante su turno al menos: 1 armazón Kids 1 CareKit
B23: {='DOMINGO'!B23} -> 0 | F23: {=($D$5/$D$31)*D23} | G23: {=(($D$8-$O$5)/$D$31)*D23}
B24: {='DOMINGO'!B24} -> 0 | F24: {=($D$5/$D$31)*D24} | G24: {=(($D$8-$O$5)/$D$31)*D24}
B25: {='DOMINGO'!B25} -> 0 | F25: {=($D$5/$D$31)*D25} | G25: {=(($D$8-$O$5)/$D$31)*D25}
B26: {='DOMINGO'!B26} -> 0 | F26: {=($D$5/$D$31)*D26} | G26: {=(($D$8-$O$5)/$D$31)*D26}
B27: {='DOMINGO'!B27} -> 0 | F27: {=($D$5/$D$31)*D27} | G27: {=(($D$8-$O$5)/$D$31)*D27}
B28: {='DOMINGO'!B28} -> 0 | F28: {=($D$5/$D$31)*D28} | G28: {=(($D$8-$O$5)/$D$31)*D28}
B29: {='DOMINGO'!B29} -> 0 | F29: {=($D$5/$D$31)*D29} | G29: {=(($D$8-$O$5)/$D$31)*D29}
B30: {='DOMINGO'!B30} -> 0 | F30: {=($D$5/$D$31)*D30} | G30: {=(($D$8-$O$5)/$D$31)*D30}
B31: TOTAL | D31: {=SUM(D23:D30)} -> 0 | F31: {=SUM(F23:F30)} | G31: {=SUM(G23:H30)} | I31: {=SUM(I23:I30)} -> 0 | K31: {=O6} | L31: {=O7}
A33: ¿CÓMO VAMOS?
B35: TOTAL DEL DÍA | D35: META | E35: VENTA NETA | F35: META UNIDADES | G35: VENTA UNIDADES | H35: CONVERSION (%) | I35: CRECIMIENTO CONVERSION (%) | K35: WEARABLES % | L35: KIDS% | M35: CAREKITS% | N35: SLP | P35: ONESIGHT
D36: {=D5} -> 0 | E36: {=H48} -> 0 | F36: {=D8} | G36: {=I48+K48} -> 0 | H36: {=F48/E48} | I36: {=H36-J6} | K36: {=K48/G36} | L36: {=M48/G36} | M36: {=N48/G36}
B39: COLABORADOR | D39: HORAS PROGRAMADAS | E39: INTERACCIONES DURANTE EL DÍA | F39: CLIENTES CONVERTIDOS DURANTE EL DÍA | G39: CONVERSION AL CIERRE | H39: VENTA NETA AL CIERRE | I39: UNIDADES ANALOGAS AL CIERRE | J39: DEMOSTRACIONES WEARABLES AL CIERRE | K39: UNIDADES WEARABLES AL CIERRE | L39: CONVERSION WEREABLE | M39: KIDS AL CIERRE | N39: CAREKITS AL CIERRE | R39: SLP EOD
B40: {=B23} -> 0 | D40: {=D23} -> 0 | G40: {=_xlfn.IFERROR(F40/E40,"0")} -> 0 | L40: {=_xlfn.IFERROR(K40/J40,"0")} -> 0
B41: {=B24} -> 0 | D41: {=D24} -> 0 | G41: {=_xlfn.IFERROR(F41/E41,"0")} -> 0 | L41: {=_xlfn.IFERROR(K41/J41,"0")} -> 0
B42: {=B25} -> 0 | D42: {=D25} -> 0 | G42: {=_xlfn.IFERROR(F42/E42,"0")} -> 0 | L42: {=_xlfn.IFERROR(K42/J42,"0")} -> 0
B43: {=B26} -> 0 | D43: {=D26} -> 0 | G43: {=_xlfn.IFERROR(F43/E43,"0")} -> 0 | L43: {=_xlfn.IFERROR(K43/J43,"0")} -> 0
B44: {=B27} -> 0 | D44: {=D27} -> 0 | G44: {=_xlfn.IFERROR(F44/E44,"0")} -> 0 | L44: {=_xlfn.IFERROR(K44/J44,"0")} -> 0
B45: {=B28} -> 0 | D45: {=D28} -> 0 | G45: {=_xlfn.IFERROR(F45/E45,"0")} -> 0 | L45: {=_xlfn.IFERROR(K45/J45,"0")} -> 0
B46: {=B29} -> 0 | D46: {=D29} -> 0 | G46: {=_xlfn.IFERROR(F46/E46,"0")} -> 0 | L46: {=_xlfn.IFERROR(K46/J46,"0")} -> 0
B47: {=B30} -> 0 | D47: {=D30} -> 0 | G47: {=_xlfn.IFERROR(F47/E47,"0")} -> 0 | L47: {=_xlfn.IFERROR(K47/J47,"0")} -> 0
B48: TOTAL | D48: {=SUM(D40:D42)} -> 0 | E48: {=SUM(E40:E47)} -> 0 | F48: {=SUM(F40:F47)} -> 0 | G48: {=_xlfn.IFERROR(F48/E48,"0")} -> 0 | H48: {=SUM(H40:H47)} -> 0 | I48: {=SUM(I40:I47)} -> 0 | J48: {=SUM(J40:J47)} -> 0 | K48: {=SUM(K40:K47)} -> 0 | L48: {=_xlfn.IFERROR(K48/J48,"0")} -> 0 | M48: {=SUM(M40:M47)} -> 0 | N48: {=SUM(N40:N47)} -> 0 | Q48: 3

Sheet PLAN ACCION JUEVES 
C1: ENFOQUE DIARIO! - Nuestro plan de acción | I1: Semana: | K1: Día: | N1: LAS CELDAS EN COLOR VERDE SE LLENAN AUTOMÁTICAMENTE
A2: ¿QÚE ESPERAMOS PARA EL DÍA DE HOY?
B4: HORAS PROGRAMADAS | C4: META (NS) | D4: META PIEZAS | E4: META (NS) PRODUCTIVIDAD | F4: META UNIDADES PRODUCTIVIDAD | I4: ¿Cuál debe ser nuestro ritmo de venta hoy?
B5: {='JUEVES'!D31} -> 0 | C5: {='JUEVES'!D5} -> 0 | D5: {='JUEVES'!D8} | E5: {='JUEVES'!D12} | F5: {='JUEVES'!D13}
B7: NUESTROS ESTÁNDARES | I7: NUESTROS NO NEGOCIABLES
B9: LIMPIEZA DE LA TIENDA Barre, limpia y desinfecta. Asegúrate de que la tienda luzca impecable. Pon especial atención al piso de ventas, aparadores, espejos, mobiliario, puerta de acceso, baño y almacén. | I9: RECORDATORIO DE ENTRADA Y SALIDA Al iniciar el día, recuerda al equipo registrar su entrada y, al finalizar su turno, registrar su salida. La precisión de estos registros impacta directamente en los indicadores de productividad.
B10: IMAGEN PERSONAL Somos embajadores de la marca, por lo que nuestra imagen debe reflejar los valores de Sunglass Hut. | I10: SIN USO DE TELÉFONOS CELULARES Evita el uso del teléfono personal durante la jornada laboral. La navegación, publicaciones y mensajes personales deben realizarse fuera del horario de trabajo.
B11: REÚNETE CON EL EQUIPO La junta matutina es clave para tener un gran día. Asegúrate de comunicar: Cómo vamos en la semana y en el mes. La meta del día y las acciones clave para alcanzarla. | I11: MANTENTE FUERA DE LA CAJA Y RESPETA TU ZONA (si aplica) A menos que estés realizando una venta en caja, evita permanecer detrás del mostrador. Si tienes una zona asignada, respétala. Mantén una actitud positiva y utiliza tu energía para atraer clientes a la tienda.
I12: EL SEGUIMIENTO ES FUNDAMENTAL Durante todo el día da seguimiento al desempeño de cada colaborador. El Store Dashboard es la principal herramienta para monitorear resultados, impulsar el desempeño y reaccionar oportunamente cuando las ventas sean lentas.
B14: LOS CINCO SECRETOS / BRANDIES | I14: CUSTOMER JOURNEY
B16: PULIR ES PODER Tu paño de limpieza es una herramienta para generar conexión con el cliente y demostrar el valor del producto. Ofrece limpiar sus lentes al iniciar la conversación para crear una experiencia positiva desde el primer contacto. | I16: EMPIEZA UNA RELACION | L16: GÁNATE SU CONFIANZA | O16: GANA LEALTAD
B17: PÓNTELOS Cuando el cliente se prueba los productos, aumenta su interés y la intención de compra. Utiliza la bandeja de exhibición para ayudarle a comparar opciones e invítalo a probar diferentes modelos hasta encontrar el ideal. | I17: INTERACTÚA Y RELACIONA | L17: DESCUBRE Y APRENDE | O17: VE MÁS ALLÁ
B18: DIVIÉRTETE MÁS La venta no termina con el primer par. Aprovecha la oportunidad para mostrar tres o cuatro opciones adicionales y aumentar las posibilidades de realizar una venta múltiple. | I18: Da la bienvenida genuinamente. | L18: Identifica necesidades (emocional/racional). | O18: Guía la compra con preguntas cerradas.
B19: CUIDALOS Enseñar al cliente cómo cuidar sus lentes mejora su experiencia y fortalece tu papel como asesor especializado. | I19: Observa al cliente y adapta tu acercamiento. | L19: Haz preguntas abiertas, escucha. | O19: Propón formas de pago alternativas.
B20: AJUSTE PERFECTO Un cliente se siente mucho más satisfecho cuando sus lentes quedan perfectamente ajustados. Dedica el tiempo necesario para lograr un ajuste cómodo y personalizado. | I20: Ofrécete a limpiar y ajustar sus gafas. | L20: Recomienda múltiples. | O20: Demuestra que te preocupas, explica cómo cuidar su compra y vuelve a ofrecer Care Kits.
I21: Descubre el próposito de la visita. | L21: Presenta las características como beneficios. | O21: Registra sus datos para el programa de lealtad.
I22: Presenta Wearables, Smart Shopper y las novedades. | L22: Comparte tu experiencia en formas y estilos. Aprovecha promociones y realiza venta adicional (Cross Selling). | O22: Invítalo a compartir su experiencia de compra mediante la encuesta (NPS).
L23: Ofrece Care Kits. | O23: Invítalo a regresar para futuras compras y seguimiento a posibles garantías.
L24: Gestiona las objeciones como oportunidades.
A28: TU ENFOQUE PARA HOY
A29: S: ESPECÍFICO
A30: M: MEDIBLE
A31: A: ALCANZABLE
A32: R: RETO
A33: T: TIEMPO
A34: LOGROS DE HOY Y OPORTUNIDADES PARA MAÑANA

Sheet VIERNES
C1: ENFOQUE DIARIO! - Nuestra meta | H1: Semana: | K1: Día: | M1: Tienda: | O1: LAS CELDAS EN COLOR VERDE SE LLENAN AUTOMÁTICAMENTE
A2: ¿QÚE ESPERAMOS LOGRAR HOY?
B4: META DEL DÍA | G4: CONVERSIÓN (NO NEGOCIABLE) | L4: OTROS NO NEGOCIABLES | O4: UNIDADES
B5: META DIARIA | G5: TRÁFICO ESPERADO | L5: WEARABLES | N5: 0.15 | O5: {=IF(D7/8100<1,1,D7/8100)} -> 1
B6: ANÁLOGOS | D6: {=D5*0.85} -> 0 | G6: META DE CONVERSIÓN (LY+1P.P) | L6: KIDS | N6: 0.05 | O6: {=IF(D8*N6<1,1,D8*N6)}
B7: WEARABLES | D7: {=D5*0.15} -> 0 | G7: META TRANSACCIONES | J7: {=J5*J6} -> 0 | L7: CAREKITS | N7: 0.3 | O7: {=IF(D8*N7<1,1,D8*N7)}
B8: TOTAL DE UNIDADES | D8: {=D5/N14} | G8: META IDEAL (NS)* | J8: {=D5*1.1} -> 0 | L8: *Si las unidades dan como resultado menor a cero, el objetivo será mínimo una unidad.
G9: *Si tienes adeudo en la semana puedes ajustar la meta ideal
L10: VALORES ACUMULADOS DEL MES (MTD) | N10: VALORES DEL DÍA COMP
B11: META DE PRODUCTIVIDAD | G11: COMP LY | L11: ATV | N11: ATV
B12: VENTA NETA (NS) | D12: {=D5/D31} | G12: VENTA NETA LY (NS)
B13: UNIDADES | D13: {=D8/D31} | L13: AUR | N13: AUR
C16: APERTURA-12pm | D16: 1pm - 2pm | E16: 3pm-4pm | F16: 5pm-6pm | G16: 7pm-CIERRE | H16: TOTAL
B17: TRÁFICO POR HORA | H17: {=SUM(C17:G17)} -> 0
B18: PESO DEL TRÁFICO (%) | C18: {=C17/$H$17} | D18: {=D17/$H$17} | E18: {=E17/$H$17} | F18: {=F17/$H$17} | G18: {=G17/$H$17} | H18: {=H17/$H$17}
B19: META (NS) X HORA | C19: {=C18*$D$5} | D19: {=D18*$D$5} | E19: {=E18*$D$5} | F19: {=F18*$D$5} | G19: {=G18*$D$5} | H19: {=SUM(C19:G19)}
B22: COLABORADORES | D22: HORAS PROGRAMADAS | F22: META DE VENTA | G22: ANALOGOS POR VENDER | I22: WEARABLES POR VENDER | K22: KIDS POR VENDER | L22: CK POR VENDER | M22: Además de cumplir con la meta diaria de la tienda para los No Negociables, cada colaborador debe procurar vender durante su turno al menos: 1 armazón Kids 1 CareKit
B23: {='DOMINGO'!B23} -> 0 | F23: {=($D$5/$D$31)*D23} | G23: {=(($D$8-$O$5)/$D$31)*D23}
B24: {='DOMINGO'!B24} -> 0 | F24: {=($D$5/$D$31)*D24} | G24: {=(($D$8-$O$5)/$D$31)*D24}
B25: {='DOMINGO'!B25} -> 0 | F25: {=($D$5/$D$31)*D25} | G25: {=(($D$8-$O$5)/$D$31)*D25}
B26: {='DOMINGO'!B26} -> 0 | F26: {=($D$5/$D$31)*D26} | G26: {=(($D$8-$O$5)/$D$31)*D26}
B27: {='DOMINGO'!B27} -> 0 | F27: {=($D$5/$D$31)*D27} | G27: {=(($D$8-$O$5)/$D$31)*D27}
B28: {='DOMINGO'!B28} -> 0 | F28: {=($D$5/$D$31)*D28} | G28: {=(($D$8-$O$5)/$D$31)*D28}
B29: {='DOMINGO'!B29} -> 0 | F29: {=($D$5/$D$31)*D29} | G29: {=(($D$8-$O$5)/$D$31)*D29}
B30: {='DOMINGO'!B30} -> 0 | F30: {=($D$5/$D$31)*D30} | G30: {=(($D$8-$O$5)/$D$31)*D30}
B31: TOTAL | D31: {=SUM(D23:D30)} -> 0 | F31: {=SUM(F23:F30)} | G31: {=SUM(G23:H30)} | I31: {=SUM(I23:I30)} -> 0 | K31: {=O6} | L31: {=O7}
A33: ¿CÓMO VAMOS?
B35: TOTAL DEL DÍA | D35: META | E35: VENTA NETA | F35: META UNIDADES | G35: VENTA UNIDADES | H35: CONVERSION (%) | I35: CRECIMIENTO CONVERSION (%) | K35: WEARABLES % | L35: KIDS% | M35: CAREKITS% | N35: SLP | P35: ONESIGHT
D36: {=D5} -> 0 | E36: {=H48} -> 0 | F36: {=D8} | G36: {=I48+K48} -> 0 | H36: {=F48/E48} | I36: {=H36-J6} | K36: {=K48/G36} | L36: {=M48/G36} | M36: {=N48/G36}
B39: COLABORADOR | D39: HORAS PROGRAMADAS | E39: INTERACCIONES DURANTE EL DÍA | F39: CLIENTES CONVERTIDOS DURANTE EL DÍA | G39: CONVERSION AL CIERRE | H39: VENTA NETA AL CIERRE | I39: UNIDADES ANALOGAS AL CIERRE | J39: DEMOSTRACIONES WEARABLES AL CIERRE | K39: UNIDADES WEARABLES AL CIERRE | L39: CONVERSION WEREABLE | M39: KIDS AL CIERRE | N39: CAREKITS AL CIERRE | R39: SLP EOD
B40: {=B23} -> 0 | D40: {=D23} -> 0 | G40: {=_xlfn.IFERROR(F40/E40,"0")} -> 0 | L40: {=_xlfn.IFERROR(K40/J40,"0")} -> 0
B41: {=B24} -> 0 | D41: {=D24} -> 0 | G41: {=_xlfn.IFERROR(F41/E41,"0")} -> 0 | L41: {=_xlfn.IFERROR(K41/J41,"0")} -> 0
B42: {=B25} -> 0 | D42: {=D25} -> 0 | G42: {=_xlfn.IFERROR(F42/E42,"0")} -> 0 | L42: {=_xlfn.IFERROR(K42/J42,"0")} -> 0
B43: {=B26} -> 0 | D43: {=D26} -> 0 | G43: {=_xlfn.IFERROR(F43/E43,"0")} -> 0 | L43: {=_xlfn.IFERROR(K43/J43,"0")} -> 0
B44: {=B27} -> 0 | D44: {=D27} -> 0 | G44: {=_xlfn.IFERROR(F44/E44,"0")} -> 0 | L44: {=_xlfn.IFERROR(K44/J44,"0")} -> 0
B45: {=B28} -> 0 | D45: {=D28} -> 0 | G45: {=_xlfn.IFERROR(F45/E45,"0")} -> 0 | L45: {=_xlfn.IFERROR(K45/J45,"0")} -> 0
B46: {=B29} -> 0 | D46: {=D29} -> 0 | G46: {=_xlfn.IFERROR(F46/E46,"0")} -> 0 | L46: {=_xlfn.IFERROR(K46/J46,"0")} -> 0
B47: {=B30} -> 0 | D47: {=D30} -> 0 | G47: {=_xlfn.IFERROR(F47/E47,"0")} -> 0 | L47: {=_xlfn.IFERROR(K47/J47,"0")} -> 0
B48: TOTAL | D48: {=SUM(D40:D42)} -> 0 | E48: {=SUM(E40:E47)} -> 0 | F48: {=SUM(F40:F47)} -> 0 | G48: {=_xlfn.IFERROR(F48/E48,"0")} -> 0 | H48: {=SUM(H40:H47)} -> 0 | I48: {=SUM(I40:I47)} -> 0 | J48: {=SUM(J40:J47)} -> 0 | K48: {=SUM(K40:K47)} -> 0 | L48: {=_xlfn.IFERROR(K48/J48,"0")} -> 0 | M48: {=SUM(M40:M47)} -> 0 | N48: {=SUM(N40:N47)} -> 0 | Q48: 3

Sheet PLAN ACCION VIERNES
C1: ENFOQUE DIARIO! - Nuestro plan de acción | I1: Semana: | K1: Día: | N1: LAS CELDAS EN COLOR VERDE SE LLENAN AUTOMÁTICAMENTE
A2: ¿QÚE ESPERAMOS PARA EL DÍA DE HOY?
B4: HORAS PROGRAMADAS | C4: META (NS) | D4: META PIEZAS | E4: META (NS) PRODUCTIVIDAD | F4: META UNIDADES PRODUCTIVIDAD | I4: ¿Cuál debe ser nuestro ritmo de venta hoy?
B5: {='VIERNES'!D31} -> 0 | C5: {='VIERNES'!D5} -> 0 | D5: {='VIERNES'!D8} | E5: {='VIERNES'!D12} | F5: {='VIERNES'!D13}
B7: NUESTROS ESTÁNDARES | I7: NUESTROS NO NEGOCIABLES
B9: LIMPIEZA DE LA TIENDA Barre, limpia y desinfecta. Asegúrate de que la tienda luzca impecable. Pon especial atención al piso de ventas, aparadores, espejos, mobiliario, puerta de acceso, baño y almacén. | I9: RECORDATORIO DE ENTRADA Y SALIDA Al iniciar el día, recuerda al equipo registrar su entrada y, al finalizar su turno, registrar su salida. La precisión de estos registros impacta directamente en los indicadores de productividad.
B10: IMAGEN PERSONAL Somos embajadores de la marca, por lo que nuestra imagen debe reflejar los valores de Sunglass Hut. | I10: SIN USO DE TELÉFONOS CELULARES Evita el uso del teléfono personal durante la jornada laboral. La navegación, publicaciones y mensajes personales deben realizarse fuera del horario de trabajo.
B11: REÚNETE CON EL EQUIPO La junta matutina es clave para tener un gran día. Asegúrate de comunicar: Cómo vamos en la semana y en el mes. La meta del día y las acciones clave para alcanzarla. | I11: MANTENTE FUERA DE LA CAJA Y RESPETA TU ZONA (si aplica) A menos que estés realizando una venta en caja, evita permanecer detrás del mostrador. Si tienes una zona asignada, respétala. Mantén una actitud positiva y utiliza tu energía para atraer clientes a la tienda.
I12: EL SEGUIMIENTO ES FUNDAMENTAL Durante todo el día da seguimiento al desempeño de cada colaborador. El Store Dashboard es la principal herramienta para monitorear resultados, impulsar el desempeño y reaccionar oportunamente cuando las ventas sean lentas.
B14: LOS CINCO SECRETOS / BRANDIES | I14: CUSTOMER JOURNEY
B16: PULIR ES PODER Tu paño de limpieza es una herramienta para generar conexión con el cliente y demostrar el valor del producto. Ofrece limpiar sus lentes al iniciar la conversación para crear una experiencia positiva desde el primer contacto. | I16: EMPIEZA UNA RELACION | L16: GÁNATE SU CONFIANZA | O16: GANA LEALTAD
B17: PÓNTELOS Cuando el cliente se prueba los productos, aumenta su interés y la intención de compra. Utiliza la bandeja de exhibición para ayudarle a comparar opciones e invítalo a probar diferentes modelos hasta encontrar el ideal. | I17: INTERACTÚA Y RELACIONA | L17: DESCUBRE Y APRENDE | O17: VE MÁS ALLÁ
B18: DIVIÉRTETE MÁS La venta no termina con el primer par. Aprovecha la oportunidad para mostrar tres o cuatro opciones adicionales y aumentar las posibilidades de realizar una venta múltiple. | I18: Da la bienvenida genuinamente. | L18: Identifica necesidades (emocional/racional). | O18: Guía la compra con preguntas cerradas.
B19: CUIDALOS Enseñar al cliente cómo cuidar sus lentes mejora su experiencia y fortalece tu papel como asesor especializado. | I19: Observa al cliente y adapta tu acercamiento. | L19: Haz preguntas abiertas, escucha. | O19: Propón formas de pago alternativas.
B20: AJUSTE PERFECTO Un cliente se siente mucho más satisfecho cuando sus lentes quedan perfectamente ajustados. Dedica el tiempo necesario para lograr un ajuste cómodo y personalizado. | I20: Ofrécete a limpiar y ajustar sus gafas. | L20: Recomienda múltiples. | O20: Demuestra que te preocupas, explica cómo cuidar su compra y vuelve a ofrecer Care Kits.
I21: Descubre el próposito de la visita. | L21: Presenta las características como beneficios. | O21: Registra sus datos para el programa de lealtad.
I22: Presenta Wearables, Smart Shopper y las novedades. | L22: Comparte tu experiencia en formas y estilos. Aprovecha promociones y realiza venta adicional (Cross Selling). | O22: Invítalo a compartir su experiencia de compra mediante la encuesta (NPS).
L23: Ofrece Care Kits. | O23: Invítalo a regresar para futuras compras y seguimiento a posibles garantías.
L24: Gestiona las objeciones como oportunidades.
A28: TU ENFOQUE PARA HOY
A29: S: ESPECÍFICO
A30: M: MEDIBLE
A31: A: ALCANZABLE
A32: R: RETO
A33: T: TIEMPO
A34: LOGROS DE HOY Y OPORTUNIDADES PARA MAÑANA

Sheet SÁBADO
C1: ENFOQUE DIARIO! - Nuestra meta | H1: Semana: | K1: Día: | M1: Tienda: | O1: LAS CELDAS EN COLOR VERDE SE LLENAN AUTOMÁTICAMENTE
A2: ¿QÚE ESPERAMOS LOGRAR HOY?
B4: META DEL DÍA | G4: CONVERSIÓN (NO NEGOCIABLE) | L4: OTROS NO NEGOCIABLES | O4: UNIDADES
B5: META DIARIA | G5: TRÁFICO ESPERADO | L5: WEARABLES | N5: 0.15 | O5: {=IF(D7/8100<1,1,D7/8100)} -> 1
B6: ANÁLOGOS | D6: {=D5*0.85} -> 0 | G6: META DE CONVERSIÓN (LY+1P.P) | L6: KIDS | N6: 0.05 | O6: {=IF(D8*N6<1,1,D8*N6)}
B7: WEARABLES | D7: {=D5*0.15} -> 0 | G7: META TRANSACCIONES | J7: {=J5*J6} -> 0 | L7: CAREKITS | N7: 0.3 | O7: {=IF(D8*N7<1,1,D8*N7)}
B8: TOTAL DE UNIDADES | D8: {=D5/N14} | G8: META IDEAL (NS)* | J8: {=D5*1.1} -> 0 | L8: *Si las unidades dan como resultado menor a cero, el objetivo será mínimo una unidad.
G9: *Si tienes adeudo en la semana puedes ajustar la meta ideal
L10: VALORES ACUMULADOS DEL MES (MTD) | N10: VALORES DEL DÍA COMP
B11: META DE PRODUCTIVIDAD | G11: COMP LY | L11: ATV | N11: ATV
B12: VENTA NETA (NS) | D12: {=D5/D31} | G12: VENTA NETA LY (NS)
B13: UNIDADES | D13: {=D8/D31} | L13: AUR | N13: AUR
C16: APERTURA-12pm | D16: 1pm - 2pm | E16: 3pm-4pm | F16: 5pm-6pm | G16: 7pm-CIERRE | H16: TOTAL
B17: TRÁFICO POR HORA | H17: {=SUM(C17:G17)} -> 0
B18: PESO DEL TRÁFICO (%) | C18: {=C17/$H$17} | D18: {=D17/$H$17} | E18: {=E17/$H$17} | F18: {=F17/$H$17} | G18: {=G17/$H$17} | H18: {=H17/$H$17}
B19: META (NS) X HORA | C19: {=C18*$D$5} | D19: {=D18*$D$5} | E19: {=E18*$D$5} | F19: {=F18*$D$5} | G19: {=G18*$D$5} | H19: {=SUM(C19:G19)}
B22: COLABORADORES | D22: HORAS PROGRAMADAS | F22: META DE VENTA | G22: ANALOGOS POR VENDER | I22: WEARABLES POR VENDER | K22: KIDS POR VENDER | L22: CK POR VENDER | M22: Además de cumplir con la meta diaria de la tienda para los No Negociables, cada colaborador debe procurar vender durante su turno al menos: 1 armazón Kids 1 CareKit
B23: {='DOMINGO'!B23} -> 0 | F23: {=($D$5/$D$31)*D23} | G23: {=(($D$8-$O$5)/$D$31)*D23}
B24: {='DOMINGO'!B24} -> 0 | F24: {=($D$5/$D$31)*D24} | G24: {=(($D$8-$O$5)/$D$31)*D24}
B25: {='DOMINGO'!B25} -> 0 | F25: {=($D$5/$D$31)*D25} | G25: {=(($D$8-$O$5)/$D$31)*D25}
B26: {='DOMINGO'!B26} -> 0 | F26: {=($D$5/$D$31)*D26} | G26: {=(($D$8-$O$5)/$D$31)*D26}
B27: {='DOMINGO'!B27} -> 0 | F27: {=($D$5/$D$31)*D27} | G27: {=(($D$8-$O$5)/$D$31)*D27}
B28: {='DOMINGO'!B28} -> 0 | F28: {=($D$5/$D$31)*D28} | G28: {=(($D$8-$O$5)/$D$31)*D28}
B29: {='DOMINGO'!B29} -> 0 | F29: {=($D$5/$D$31)*D29} | G29: {=(($D$8-$O$5)/$D$31)*D29}
B30: {='DOMINGO'!B30} -> 0 | F30: {=($D$5/$D$31)*D30} | G30: {=(($D$8-$O$5)/$D$31)*D30}
B31: TOTAL | D31: {=SUM(D23:D30)} -> 0 | F31: {=SUM(F23:F30)} | G31: {=SUM(G23:H30)} | I31: {=SUM(I23:I30)} -> 0 | K31: {=O6} | L31: {=O7}
A33: ¿CÓMO VAMOS?
B35: TOTAL DEL DÍA | D35: META | E35: VENTA NETA | F35: META UNIDADES | G35: VENTA UNIDADES | H35: CONVERSION (%) | I35: CRECIMIENTO CONVERSION (%) | K35: WEARABLES % | L35: KIDS% | M35: CAREKITS% | N35: SLP | P35: ONESIGHT
D36: {=D5} -> 0 | E36: {=H48} -> 0 | F36: {=D8} | G36: {=I48+K48} -> 0 | H36: {=F48/E48} | I36: {=H36-J6} | K36: {=K48/G36} | L36: {=M48/G36} | M36: {=N48/G36}
B39: COLABORADOR | D39: HORAS PROGRAMADAS | E39: INTERACCIONES DURANTE EL DÍA | F39: CLIENTES CONVERTIDOS DURANTE EL DÍA | G39: CONVERSION AL CIERRE | H39: VENTA NETA AL CIERRE | I39: UNIDADES ANALOGAS AL CIERRE | J39: DEMOSTRACIONES WEARABLES AL CIERRE | K39: UNIDADES WEARABLES AL CIERRE | L39: CONVERSION WEREABLE | M39: KIDS AL CIERRE | N39: CAREKITS AL CIERRE | R39: SLP EOD
B40: {=B23} -> 0 | D40: {=D23} -> 0 | G40: {=_xlfn.IFERROR(F40/E40,"0")} -> 0 | L40: {=_xlfn.IFERROR(K40/J40,"0")} -> 0
B41: {=B24} -> 0 | D41: {=D24} -> 0 | G41: {=_xlfn.IFERROR(F41/E41,"0")} -> 0 | L41: {=_xlfn.IFERROR(K41/J41,"0")} -> 0
B42: {=B25} -> 0 | D42: {=D25} -> 0 | G42: {=_xlfn.IFERROR(F42/E42,"0")} -> 0 | L42: {=_xlfn.IFERROR(K42/J42,"0")} -> 0
B43: {=B26} -> 0 | D43: {=D26} -> 0 | G43: {=_xlfn.IFERROR(F43/E43,"0")} -> 0 | L43: {=_xlfn.IFERROR(K43/J43,"0")} -> 0
B44: {=B27} -> 0 | D44: {=D27} -> 0 | G44: {=_xlfn.IFERROR(F44/E44,"0")} -> 0 | L44: {=_xlfn.IFERROR(K44/J44,"0")} -> 0
B45: {=B28} -> 0 | D45: {=D28} -> 0 | G45: {=_xlfn.IFERROR(F45/E45,"0")} -> 0 | L45: {=_xlfn.IFERROR(K45/J45,"0")} -> 0
B46: {=B29} -> 0 | D46: {=D29} -> 0 | G46: {=_xlfn.IFERROR(F46/E46,"0")} -> 0 | L46: {=_xlfn.IFERROR(K46/J46,"0")} -> 0
B47: {=B30} -> 0 | D47: {=D30} -> 0 | G47: {=_xlfn.IFERROR(F47/E47,"0")} -> 0 | L47: {=_xlfn.IFERROR(K47/J47,"0")} -> 0
B48: TOTAL | D48: {=SUM(D40:D42)} -> 0 | E48: {=SUM(E40:E47)} -> 0 | F48: {=SUM(F40:F47)} -> 0 | G48: {=_xlfn.IFERROR(F48/E48,"0")} -> 0 | H48: {=SUM(H40:H47)} -> 0 | I48: {=SUM(I40:I47)} -> 0 | J48: {=SUM(J40:J47)} -> 0 | K48: {=SUM(K40:K47)} -> 0 | L48: {=_xlfn.IFERROR(K48/J48,"0")} -> 0 | M48: {=SUM(M40:M47)} -> 0 | N48: {=SUM(N40:N47)} -> 0 | Q48: 3

Sheet PLAN ACCION SÁBADO 
C1: ENFOQUE DIARIO! - Nuestro plan de acción | I1: Semana: | K1: Día: | N1: LAS CELDAS EN COLOR VERDE SE LLENAN AUTOMÁTICAMENTE
A2: ¿QÚE ESPERAMOS PARA EL DÍA DE HOY?
